[2024-09-19T00:45:19.928+0000] {local_task_job_runner.py:123} INFO - ::group::Pre task execution logs
[2024-09-19T00:45:19.949+0000] {taskinstance.py:2612} INFO - Dependencies all met for dep_context=non-requeueable deps ti=<TaskInstance: nba_data_pipeline.run_data_processing manual__2024-09-19T00:44:36.928174+00:00 [queued]>
[2024-09-19T00:45:19.960+0000] {taskinstance.py:2612} INFO - Dependencies all met for dep_context=requeueable deps ti=<TaskInstance: nba_data_pipeline.run_data_processing manual__2024-09-19T00:44:36.928174+00:00 [queued]>
[2024-09-19T00:45:19.960+0000] {taskinstance.py:2865} INFO - Starting attempt 1 of 2
[2024-09-19T00:45:19.976+0000] {taskinstance.py:2888} INFO - Executing <Task(DockerOperator): run_data_processing> on 2024-09-19 00:44:36.928174+00:00
[2024-09-19T00:45:19.984+0000] {standard_task_runner.py:104} INFO - Running: ['airflow', 'tasks', 'run', 'nba_data_pipeline', 'run_data_processing', 'manual__2024-09-19T00:44:36.928174+00:00', '--job-id', '7', '--raw', '--subdir', 'DAGS_FOLDER/nba_data_pipeline.py', '--cfg-path', '/tmp/tmpr7g7xgzk']
[2024-09-19T00:45:19.987+0000] {standard_task_runner.py:105} INFO - Job 7: Subtask run_data_processing
[2024-09-19T00:45:19.989+0000] {logging_mixin.py:190} WARNING - /home/airflow/.local/lib/python3.12/site-packages/airflow/task/task_runner/standard_task_runner.py:70 DeprecationWarning: This process (pid=260) is multi-threaded, use of fork() may lead to deadlocks in the child.
[2024-09-19T00:45:19.990+0000] {standard_task_runner.py:72} INFO - Started process 261 to run task
[2024-09-19T00:45:20.041+0000] {task_command.py:467} INFO - Running <TaskInstance: nba_data_pipeline.run_data_processing manual__2024-09-19T00:44:36.928174+00:00 [running]> on host 60f4d263d5b1
[2024-09-19T00:45:20.140+0000] {taskinstance.py:3131} INFO - Exporting env vars: AIRFLOW_CTX_DAG_OWNER='airflow' AIRFLOW_CTX_DAG_ID='nba_data_pipeline' AIRFLOW_CTX_TASK_ID='run_data_processing' AIRFLOW_CTX_EXECUTION_DATE='2024-09-19T00:44:36.928174+00:00' AIRFLOW_CTX_TRY_NUMBER='1' AIRFLOW_CTX_DAG_RUN_ID='manual__2024-09-19T00:44:36.928174+00:00'
[2024-09-19T00:45:20.142+0000] {taskinstance.py:731} INFO - ::endgroup::
[2024-09-19T00:45:20.171+0000] {docker.py:367} INFO - Starting docker container from image us-west1-docker.pkg.dev/nba-fantasy-ml/nba-data-pipeline-repo/data-processing:latest
[2024-09-19T00:45:20.180+0000] {docker.py:375} WARNING - Using remote engine or docker-in-docker and mounting temporary volume from host is not supported. Falling back to `mount_tmp_dir=False` mode. You can set `mount_tmp_dir` parameter to False to disable mounting and remove the warning
[2024-09-19T00:45:21.021+0000] {docker.py:438} INFO - 2024-09-19 00:45:21,019 - WARNING - Retrying (Retry(total=4, connect=None, read=None, redirect=None, status=None)) after connection broken by 'NameResolutionError("<urllib3.connection.HTTPConnection object at 0x7f7af681e2f0>: Failed to resolve 'minio' ([Errno -2] Name or service not known)")': /nba-raw-data?location=
[2024-09-19T00:45:21.427+0000] {docker.py:438} INFO - 2024-09-19 00:45:21,425 - WARNING - Retrying (Retry(total=3, connect=None, read=None, redirect=None, status=None)) after connection broken by 'NameResolutionError("<urllib3.connection.HTTPConnection object at 0x7f7af681e620>: Failed to resolve 'minio' ([Errno -2] Name or service not known)")': /nba-raw-data?location=
[2024-09-19T00:45:22.234+0000] {docker.py:438} INFO - 2024-09-19 00:45:22,232 - WARNING - Retrying (Retry(total=2, connect=None, read=None, redirect=None, status=None)) after connection broken by 'NameResolutionError("<urllib3.connection.HTTPConnection object at 0x7f7af681eb30>: Failed to resolve 'minio' ([Errno -2] Name or service not known)")': /nba-raw-data?location=
[2024-09-19T00:45:23.842+0000] {docker.py:438} INFO - 2024-09-19 00:45:23,840 - WARNING - Retrying (Retry(total=1, connect=None, read=None, redirect=None, status=None)) after connection broken by 'NameResolutionError("<urllib3.connection.HTTPConnection object at 0x7f7af681ed40>: Failed to resolve 'minio' ([Errno -2] Name or service not known)")': /nba-raw-data?location=
[2024-09-19T00:45:27.051+0000] {docker.py:438} INFO - 2024-09-19 00:45:27,049 - WARNING - Retrying (Retry(total=0, connect=None, read=None, redirect=None, status=None)) after connection broken by 'NameResolutionError("<urllib3.connection.HTTPConnection object at 0x7f7af681eef0>: Failed to resolve 'minio' ([Errno -2] Name or service not known)")': /nba-raw-data?location=
[2024-09-19T00:45:27.056+0000] {docker.py:438} INFO - 2024-09-19 00:45:27,054 - ERROR - Error in data processing: HTTPConnectionPool(host='minio', port=9000): Max retries exceeded with url: /nba-raw-data?location= (Caused by NameResolutionError("<urllib3.connection.HTTPConnection object at 0x7f7af681f0a0>: Failed to resolve 'minio' ([Errno -2] Name or service not known)"))
[2024-09-19T00:45:27.284+0000] {taskinstance.py:340} INFO - ::group::Post task execution logs
[2024-09-19T00:45:27.284+0000] {taskinstance.py:352} INFO - Marking task as SUCCESS. dag_id=nba_data_pipeline, task_id=run_data_processing, run_id=manual__2024-09-19T00:44:36.928174+00:00, execution_date=20240919T004436, start_date=20240919T004519, end_date=20240919T004527
[2024-09-19T00:45:27.331+0000] {local_task_job_runner.py:266} INFO - Task exited with return code 0
[2024-09-19T00:45:27.349+0000] {taskinstance.py:3900} INFO - 0 downstream tasks scheduled from follow-on schedule check
[2024-09-19T00:45:27.351+0000] {local_task_job_runner.py:245} INFO - ::endgroup::
