[2024-09-19T00:42:41.303+0000] {local_task_job_runner.py:123} INFO - ::group::Pre task execution logs
[2024-09-19T00:42:41.323+0000] {taskinstance.py:2612} INFO - Dependencies all met for dep_context=non-requeueable deps ti=<TaskInstance: nba_data_pipeline.run_data_processing manual__2024-09-19T00:41:56.858789+00:00 [queued]>
[2024-09-19T00:42:41.334+0000] {taskinstance.py:2612} INFO - Dependencies all met for dep_context=requeueable deps ti=<TaskInstance: nba_data_pipeline.run_data_processing manual__2024-09-19T00:41:56.858789+00:00 [queued]>
[2024-09-19T00:42:41.334+0000] {taskinstance.py:2865} INFO - Starting attempt 1 of 2
[2024-09-19T00:42:41.349+0000] {taskinstance.py:2888} INFO - Executing <Task(DockerOperator): run_data_processing> on 2024-09-19 00:41:56.858789+00:00
[2024-09-19T00:42:41.357+0000] {standard_task_runner.py:104} INFO - Running: ['airflow', 'tasks', 'run', 'nba_data_pipeline', 'run_data_processing', 'manual__2024-09-19T00:41:56.858789+00:00', '--job-id', '5', '--raw', '--subdir', 'DAGS_FOLDER/nba_data_pipeline.py', '--cfg-path', '/tmp/tmpf5sdjf1s']
[2024-09-19T00:42:41.360+0000] {standard_task_runner.py:105} INFO - Job 5: Subtask run_data_processing
[2024-09-19T00:42:41.362+0000] {logging_mixin.py:190} WARNING - /home/airflow/.local/lib/python3.12/site-packages/airflow/task/task_runner/standard_task_runner.py:70 DeprecationWarning: This process (pid=224) is multi-threaded, use of fork() may lead to deadlocks in the child.
[2024-09-19T00:42:41.363+0000] {standard_task_runner.py:72} INFO - Started process 225 to run task
[2024-09-19T00:42:41.411+0000] {task_command.py:467} INFO - Running <TaskInstance: nba_data_pipeline.run_data_processing manual__2024-09-19T00:41:56.858789+00:00 [running]> on host 60f4d263d5b1
[2024-09-19T00:42:41.500+0000] {taskinstance.py:3131} INFO - Exporting env vars: AIRFLOW_CTX_DAG_OWNER='airflow' AIRFLOW_CTX_DAG_ID='nba_data_pipeline' AIRFLOW_CTX_TASK_ID='run_data_processing' AIRFLOW_CTX_EXECUTION_DATE='2024-09-19T00:41:56.858789+00:00' AIRFLOW_CTX_TRY_NUMBER='1' AIRFLOW_CTX_DAG_RUN_ID='manual__2024-09-19T00:41:56.858789+00:00'
[2024-09-19T00:42:41.501+0000] {taskinstance.py:731} INFO - ::endgroup::
[2024-09-19T00:42:41.530+0000] {docker.py:367} INFO - Starting docker container from image us-west1-docker.pkg.dev/nba-fantasy-ml/nba-data-pipeline-repo/data-processing:latest
[2024-09-19T00:42:41.538+0000] {docker.py:375} WARNING - Using remote engine or docker-in-docker and mounting temporary volume from host is not supported. Falling back to `mount_tmp_dir=False` mode. You can set `mount_tmp_dir` parameter to False to disable mounting and remove the warning
[2024-09-19T00:42:42.388+0000] {docker.py:438} INFO - 2024-09-19 00:42:42,386 - WARNING - Retrying (Retry(total=4, connect=None, read=None, redirect=None, status=None)) after connection broken by 'NameResolutionError("<urllib3.connection.HTTPConnection object at 0x7fd914ebe2f0>: Failed to resolve 'minio' ([Errno -2] Name or service not known)")': /nba-raw-data?location=
[2024-09-19T00:42:42.794+0000] {docker.py:438} INFO - 2024-09-19 00:42:42,792 - WARNING - Retrying (Retry(total=3, connect=None, read=None, redirect=None, status=None)) after connection broken by 'NameResolutionError("<urllib3.connection.HTTPConnection object at 0x7fd914ebe620>: Failed to resolve 'minio' ([Errno -2] Name or service not known)")': /nba-raw-data?location=
[2024-09-19T00:42:43.601+0000] {docker.py:438} INFO - 2024-09-19 00:42:43,599 - WARNING - Retrying (Retry(total=2, connect=None, read=None, redirect=None, status=None)) after connection broken by 'NameResolutionError("<urllib3.connection.HTTPConnection object at 0x7fd914ebeb30>: Failed to resolve 'minio' ([Errno -2] Name or service not known)")': /nba-raw-data?location=
[2024-09-19T00:42:45.207+0000] {docker.py:438} INFO - 2024-09-19 00:42:45,205 - WARNING - Retrying (Retry(total=1, connect=None, read=None, redirect=None, status=None)) after connection broken by 'NameResolutionError("<urllib3.connection.HTTPConnection object at 0x7fd914ebed40>: Failed to resolve 'minio' ([Errno -2] Name or service not known)")': /nba-raw-data?location=
[2024-09-19T00:42:48.414+0000] {docker.py:438} INFO - 2024-09-19 00:42:48,412 - WARNING - Retrying (Retry(total=0, connect=None, read=None, redirect=None, status=None)) after connection broken by 'NameResolutionError("<urllib3.connection.HTTPConnection object at 0x7fd914ebeef0>: Failed to resolve 'minio' ([Errno -2] Name or service not known)")': /nba-raw-data?location=
[2024-09-19T00:42:48.419+0000] {docker.py:438} INFO - 2024-09-19 00:42:48,418 - ERROR - Error in data processing: HTTPConnectionPool(host='minio', port=9000): Max retries exceeded with url: /nba-raw-data?location= (Caused by NameResolutionError("<urllib3.connection.HTTPConnection object at 0x7fd914ebf0a0>: Failed to resolve 'minio' ([Errno -2] Name or service not known)"))
[2024-09-19T00:42:48.691+0000] {taskinstance.py:340} INFO - ::group::Post task execution logs
[2024-09-19T00:42:48.692+0000] {taskinstance.py:352} INFO - Marking task as SUCCESS. dag_id=nba_data_pipeline, task_id=run_data_processing, run_id=manual__2024-09-19T00:41:56.858789+00:00, execution_date=20240919T004156, start_date=20240919T004241, end_date=20240919T004248
[2024-09-19T00:42:48.738+0000] {local_task_job_runner.py:266} INFO - Task exited with return code 0
[2024-09-19T00:42:48.763+0000] {taskinstance.py:3900} INFO - 0 downstream tasks scheduled from follow-on schedule check
[2024-09-19T00:42:48.765+0000] {local_task_job_runner.py:245} INFO - ::endgroup::
