[2024-09-19T08:19:10.822+0000] {local_task_job_runner.py:123} INFO - ::group::Pre task execution logs
[2024-09-19T08:19:10.846+0000] {taskinstance.py:2612} INFO - Dependencies all met for dep_context=non-requeueable deps ti=<TaskInstance: nba_data_pipeline.run_data_ingestion manual__2024-09-19T08:17:34.386157+00:00 [queued]>
[2024-09-19T08:19:10.857+0000] {taskinstance.py:2612} INFO - Dependencies all met for dep_context=requeueable deps ti=<TaskInstance: nba_data_pipeline.run_data_ingestion manual__2024-09-19T08:17:34.386157+00:00 [queued]>
[2024-09-19T08:19:10.858+0000] {taskinstance.py:2865} INFO - Starting attempt 2 of 5
[2024-09-19T08:19:10.878+0000] {taskinstance.py:2888} INFO - Executing <Task(_PythonDecoratedOperator): run_data_ingestion> on 2024-09-19 08:17:34.386157+00:00
[2024-09-19T08:19:10.886+0000] {standard_task_runner.py:104} INFO - Running: ['airflow', 'tasks', 'run', 'nba_data_pipeline', 'run_data_ingestion', 'manual__2024-09-19T08:17:34.386157+00:00', '--job-id', '16', '--raw', '--subdir', 'DAGS_FOLDER/nba_data_pipeline.py', '--cfg-path', '/tmp/tmp36m4x7zp']
[2024-09-19T08:19:10.890+0000] {standard_task_runner.py:105} INFO - Job 16: Subtask run_data_ingestion
[2024-09-19T08:19:10.892+0000] {logging_mixin.py:190} WARNING - /home/airflow/.local/lib/python3.12/site-packages/airflow/task/task_runner/standard_task_runner.py:70 DeprecationWarning: This process (pid=372) is multi-threaded, use of fork() may lead to deadlocks in the child.
[2024-09-19T08:19:10.893+0000] {standard_task_runner.py:72} INFO - Started process 373 to run task
[2024-09-19T08:19:10.949+0000] {task_command.py:467} INFO - Running <TaskInstance: nba_data_pipeline.run_data_ingestion manual__2024-09-19T08:17:34.386157+00:00 [running]> on host 79e10942e2e4
[2024-09-19T08:19:11.056+0000] {taskinstance.py:3131} INFO - Exporting env vars: AIRFLOW_CTX_DAG_OWNER='airflow' AIRFLOW_CTX_DAG_ID='nba_data_pipeline' AIRFLOW_CTX_TASK_ID='run_data_ingestion' AIRFLOW_CTX_EXECUTION_DATE='2024-09-19T08:17:34.386157+00:00' AIRFLOW_CTX_TRY_NUMBER='2' AIRFLOW_CTX_DAG_RUN_ID='manual__2024-09-19T08:17:34.386157+00:00'
[2024-09-19T08:19:11.058+0000] {taskinstance.py:731} INFO - ::endgroup::
[2024-09-19T08:19:11.064+0000] {baseoperator.py:405} WARNING - DockerOperator.execute cannot be called outside TaskInstance!
[2024-09-19T08:19:11.094+0000] {docker.py:367} INFO - Starting docker container from image us-west1-docker.pkg.dev/nba-fantasy-ml/nba-data-pipeline-repo/data-ingestion:latest
[2024-09-19T08:19:20.972+0000] {local_task_job_runner.py:346} WARNING - State of this instance has been externally set to failed. Terminating instance.
[2024-09-19T08:19:20.973+0000] {local_task_job_runner.py:245} INFO - ::endgroup::
[2024-09-19T08:19:20.976+0000] {process_utils.py:132} INFO - Sending 15 to group 373. PIDs of all processes in the group: [373]
[2024-09-19T08:19:20.976+0000] {process_utils.py:87} INFO - Sending the signal 15 to group 373
[2024-09-19T08:19:20.977+0000] {taskinstance.py:3092} ERROR - Received SIGTERM. Terminating subprocesses.
[2024-09-19T08:19:20.984+0000] {taskinstance.py:3310} ERROR - Task failed with exception
Traceback (most recent call last):
  File "/home/airflow/.local/lib/python3.12/site-packages/airflow/providers/docker/operators/docker.py", line 434, in _run_image_with_mounts
    for log_chunk in logstream:
                     ^^^^^^^^^
  File "/home/airflow/.local/lib/python3.12/site-packages/docker/types/daemon.py", line 29, in __next__
    return next(self._stream)
           ^^^^^^^^^^^^^^^^^^
  File "/home/airflow/.local/lib/python3.12/site-packages/docker/api/client.py", line 438, in <genexpr>
    gen = (data for (_, data) in gen)
          ^^^^^^^^^^^^^^^^^^^^^^^^^^^
  File "/home/airflow/.local/lib/python3.12/site-packages/docker/utils/socket.py", line 112, in frames_iter_no_tty
    (stream, n) = next_frame_header(socket)
                  ^^^^^^^^^^^^^^^^^^^^^^^^^
  File "/home/airflow/.local/lib/python3.12/site-packages/docker/utils/socket.py", line 84, in next_frame_header
    data = read_exactly(socket, 8)
           ^^^^^^^^^^^^^^^^^^^^^^^
  File "/home/airflow/.local/lib/python3.12/site-packages/docker/utils/socket.py", line 69, in read_exactly
    next_data = read(socket, n - len(data))
                ^^^^^^^^^^^^^^^^^^^^^^^^^^^
  File "/home/airflow/.local/lib/python3.12/site-packages/docker/utils/socket.py", line 40, in read
    poll.poll()
  File "/home/airflow/.local/lib/python3.12/site-packages/airflow/models/taskinstance.py", line 3094, in signal_handler
    raise AirflowTaskTerminated("Task received SIGTERM signal")
airflow.exceptions.AirflowTaskTerminated: Task received SIGTERM signal

During handling of the above exception, another exception occurred:

Traceback (most recent call last):
  File "/home/airflow/.local/lib/python3.12/site-packages/docker/api/client.py", line 275, in _raise_for_status
    response.raise_for_status()
  File "/home/airflow/.local/lib/python3.12/site-packages/requests/models.py", line 1024, in raise_for_status
    raise HTTPError(http_error_msg, response=self)
requests.exceptions.HTTPError: 409 Client Error: Conflict for url: http+docker://localhost/v1.47/containers/62f76751ea9de4f38287c205a5536961c2166a0aaf0fa32946e7ed04477ecd60?v=False&link=False&force=False

The above exception was the direct cause of the following exception:

Traceback (most recent call last):
  File "/home/airflow/.local/lib/python3.12/site-packages/airflow/models/taskinstance.py", line 767, in _execute_task
    result = _execute_callable(context=context, **execute_callable_kwargs)
             ^^^^^^^^^^^^^^^^^^^^^^^^^^^^^^^^^^^^^^^^^^^^^^^^^^^^^^^^^^^^^
  File "/home/airflow/.local/lib/python3.12/site-packages/airflow/models/taskinstance.py", line 733, in _execute_callable
    return ExecutionCallableRunner(
           ^^^^^^^^^^^^^^^^^^^^^^^^
  File "/home/airflow/.local/lib/python3.12/site-packages/airflow/utils/operator_helpers.py", line 252, in run
    return self.func(*args, **kwargs)
           ^^^^^^^^^^^^^^^^^^^^^^^^^^
  File "/home/airflow/.local/lib/python3.12/site-packages/airflow/models/baseoperator.py", line 406, in wrapper
    return func(self, *args, **kwargs)
           ^^^^^^^^^^^^^^^^^^^^^^^^^^^
  File "/home/airflow/.local/lib/python3.12/site-packages/airflow/decorators/base.py", line 266, in execute
    return_value = super().execute(context)
                   ^^^^^^^^^^^^^^^^^^^^^^^^
  File "/home/airflow/.local/lib/python3.12/site-packages/airflow/models/baseoperator.py", line 406, in wrapper
    return func(self, *args, **kwargs)
           ^^^^^^^^^^^^^^^^^^^^^^^^^^^
  File "/home/airflow/.local/lib/python3.12/site-packages/airflow/operators/python.py", line 238, in execute
    return_value = self.execute_callable()
                   ^^^^^^^^^^^^^^^^^^^^^^^
  File "/home/airflow/.local/lib/python3.12/site-packages/airflow/operators/python.py", line 256, in execute_callable
    return runner.run(*self.op_args, **self.op_kwargs)
           ^^^^^^^^^^^^^^^^^^^^^^^^^^^^^^^^^^^^^^^^^^^
  File "/home/airflow/.local/lib/python3.12/site-packages/airflow/utils/operator_helpers.py", line 252, in run
    return self.func(*args, **kwargs)
           ^^^^^^^^^^^^^^^^^^^^^^^^^^
  File "/opt/airflow/dags/nba_data_pipeline.py", line 57, in run_data_ingestion
    ).execute(context=kwargs)
      ^^^^^^^^^^^^^^^^^^^^^^^
  File "/home/airflow/.local/lib/python3.12/site-packages/airflow/models/baseoperator.py", line 406, in wrapper
    return func(self, *args, **kwargs)
           ^^^^^^^^^^^^^^^^^^^^^^^^^^^
  File "/home/airflow/.local/lib/python3.12/site-packages/airflow/providers/docker/operators/docker.py", line 513, in execute
    return self._run_image()
           ^^^^^^^^^^^^^^^^^
  File "/home/airflow/.local/lib/python3.12/site-packages/airflow/providers/docker/operators/docker.py", line 384, in _run_image
    return self._run_image_with_mounts(self.mounts, add_tmp_variable=False)
           ^^^^^^^^^^^^^^^^^^^^^^^^^^^^^^^^^^^^^^^^^^^^^^^^^^^^^^^^^^^^^^^^
  File "/home/airflow/.local/lib/python3.12/site-packages/airflow/providers/docker/operators/docker.py", line 464, in _run_image_with_mounts
    self.cli.remove_container(self.container["Id"])
  File "/home/airflow/.local/lib/python3.12/site-packages/docker/utils/decorators.py", line 19, in wrapped
    return f(self, resource_id, *args, **kwargs)
           ^^^^^^^^^^^^^^^^^^^^^^^^^^^^^^^^^^^^^
  File "/home/airflow/.local/lib/python3.12/site-packages/docker/api/container.py", line 1037, in remove_container
    self._raise_for_status(res)
  File "/home/airflow/.local/lib/python3.12/site-packages/docker/api/client.py", line 277, in _raise_for_status
    raise create_api_error_from_http_exception(e) from e
          ^^^^^^^^^^^^^^^^^^^^^^^^^^^^^^^^^^^^^^^
  File "/home/airflow/.local/lib/python3.12/site-packages/docker/errors.py", line 39, in create_api_error_from_http_exception
    raise cls(e, response=response, explanation=explanation) from e
docker.errors.APIError: 409 Client Error for http+docker://localhost/v1.47/containers/62f76751ea9de4f38287c205a5536961c2166a0aaf0fa32946e7ed04477ecd60?v=False&link=False&force=False: Conflict ("cannot remove container "/data_ingestion": container is running: stop the container before removing or force remove")
[2024-09-19T08:19:21.002+0000] {taskinstance.py:1225} INFO - Marking task as UP_FOR_RETRY. dag_id=nba_data_pipeline, task_id=run_data_ingestion, run_id=manual__2024-09-19T08:17:34.386157+00:00, execution_date=20240919T081734, start_date=20240919T081910, end_date=20240919T081921
[2024-09-19T08:19:21.018+0000] {taskinstance.py:340} INFO - ::group::Post task execution logs
[2024-09-19T08:19:21.018+0000] {standard_task_runner.py:124} ERROR - Failed to execute job 16 for task run_data_ingestion (409 Client Error for http+docker://localhost/v1.47/containers/62f76751ea9de4f38287c205a5536961c2166a0aaf0fa32946e7ed04477ecd60?v=False&link=False&force=False: Conflict ("cannot remove container "/data_ingestion": container is running: stop the container before removing or force remove"); 373)
Traceback (most recent call last):
  File "/home/airflow/.local/lib/python3.12/site-packages/airflow/providers/docker/operators/docker.py", line 434, in _run_image_with_mounts
    for log_chunk in logstream:
                     ^^^^^^^^^
  File "/home/airflow/.local/lib/python3.12/site-packages/docker/types/daemon.py", line 29, in __next__
    return next(self._stream)
           ^^^^^^^^^^^^^^^^^^
  File "/home/airflow/.local/lib/python3.12/site-packages/docker/api/client.py", line 438, in <genexpr>
    gen = (data for (_, data) in gen)
          ^^^^^^^^^^^^^^^^^^^^^^^^^^^
  File "/home/airflow/.local/lib/python3.12/site-packages/docker/utils/socket.py", line 112, in frames_iter_no_tty
    (stream, n) = next_frame_header(socket)
                  ^^^^^^^^^^^^^^^^^^^^^^^^^
  File "/home/airflow/.local/lib/python3.12/site-packages/docker/utils/socket.py", line 84, in next_frame_header
    data = read_exactly(socket, 8)
           ^^^^^^^^^^^^^^^^^^^^^^^
  File "/home/airflow/.local/lib/python3.12/site-packages/docker/utils/socket.py", line 69, in read_exactly
    next_data = read(socket, n - len(data))
                ^^^^^^^^^^^^^^^^^^^^^^^^^^^
  File "/home/airflow/.local/lib/python3.12/site-packages/docker/utils/socket.py", line 40, in read
    poll.poll()
  File "/home/airflow/.local/lib/python3.12/site-packages/airflow/models/taskinstance.py", line 3094, in signal_handler
    raise AirflowTaskTerminated("Task received SIGTERM signal")
airflow.exceptions.AirflowTaskTerminated: Task received SIGTERM signal

During handling of the above exception, another exception occurred:

Traceback (most recent call last):
  File "/home/airflow/.local/lib/python3.12/site-packages/docker/api/client.py", line 275, in _raise_for_status
    response.raise_for_status()
  File "/home/airflow/.local/lib/python3.12/site-packages/requests/models.py", line 1024, in raise_for_status
    raise HTTPError(http_error_msg, response=self)
requests.exceptions.HTTPError: 409 Client Error: Conflict for url: http+docker://localhost/v1.47/containers/62f76751ea9de4f38287c205a5536961c2166a0aaf0fa32946e7ed04477ecd60?v=False&link=False&force=False

The above exception was the direct cause of the following exception:

Traceback (most recent call last):
  File "/home/airflow/.local/lib/python3.12/site-packages/airflow/task/task_runner/standard_task_runner.py", line 117, in _start_by_fork
    ret = args.func(args, dag=self.dag)
          ^^^^^^^^^^^^^^^^^^^^^^^^^^^^^
  File "/home/airflow/.local/lib/python3.12/site-packages/airflow/cli/cli_config.py", line 49, in command
    return func(*args, **kwargs)
           ^^^^^^^^^^^^^^^^^^^^^
  File "/home/airflow/.local/lib/python3.12/site-packages/airflow/utils/cli.py", line 115, in wrapper
    return f(*args, **kwargs)
           ^^^^^^^^^^^^^^^^^^
  File "/home/airflow/.local/lib/python3.12/site-packages/airflow/cli/commands/task_command.py", line 483, in task_run
    task_return_code = _run_task_by_selected_method(args, _dag, ti)
                       ^^^^^^^^^^^^^^^^^^^^^^^^^^^^^^^^^^^^^^^^^^^^
  File "/home/airflow/.local/lib/python3.12/site-packages/airflow/cli/commands/task_command.py", line 256, in _run_task_by_selected_method
    return _run_raw_task(args, ti)
           ^^^^^^^^^^^^^^^^^^^^^^^
  File "/home/airflow/.local/lib/python3.12/site-packages/airflow/cli/commands/task_command.py", line 341, in _run_raw_task
    return ti._run_raw_task(
           ^^^^^^^^^^^^^^^^^
  File "/home/airflow/.local/lib/python3.12/site-packages/airflow/utils/session.py", line 97, in wrapper
    return func(*args, session=session, **kwargs)
           ^^^^^^^^^^^^^^^^^^^^^^^^^^^^^^^^^^^^^^
  File "/home/airflow/.local/lib/python3.12/site-packages/airflow/models/taskinstance.py", line 3004, in _run_raw_task
    return _run_raw_task(
           ^^^^^^^^^^^^^^
  File "/home/airflow/.local/lib/python3.12/site-packages/airflow/models/taskinstance.py", line 273, in _run_raw_task
    TaskInstance._execute_task_with_callbacks(
  File "/home/airflow/.local/lib/python3.12/site-packages/airflow/models/taskinstance.py", line 3158, in _execute_task_with_callbacks
    result = self._execute_task(context, task_orig)
             ^^^^^^^^^^^^^^^^^^^^^^^^^^^^^^^^^^^^^^
  File "/home/airflow/.local/lib/python3.12/site-packages/airflow/models/taskinstance.py", line 3182, in _execute_task
    return _execute_task(self, context, task_orig)
           ^^^^^^^^^^^^^^^^^^^^^^^^^^^^^^^^^^^^^^^
  File "/home/airflow/.local/lib/python3.12/site-packages/airflow/models/taskinstance.py", line 767, in _execute_task
    result = _execute_callable(context=context, **execute_callable_kwargs)
             ^^^^^^^^^^^^^^^^^^^^^^^^^^^^^^^^^^^^^^^^^^^^^^^^^^^^^^^^^^^^^
  File "/home/airflow/.local/lib/python3.12/site-packages/airflow/models/taskinstance.py", line 733, in _execute_callable
    return ExecutionCallableRunner(
           ^^^^^^^^^^^^^^^^^^^^^^^^
  File "/home/airflow/.local/lib/python3.12/site-packages/airflow/utils/operator_helpers.py", line 252, in run
    return self.func(*args, **kwargs)
           ^^^^^^^^^^^^^^^^^^^^^^^^^^
  File "/home/airflow/.local/lib/python3.12/site-packages/airflow/models/baseoperator.py", line 406, in wrapper
    return func(self, *args, **kwargs)
           ^^^^^^^^^^^^^^^^^^^^^^^^^^^
  File "/home/airflow/.local/lib/python3.12/site-packages/airflow/decorators/base.py", line 266, in execute
    return_value = super().execute(context)
                   ^^^^^^^^^^^^^^^^^^^^^^^^
  File "/home/airflow/.local/lib/python3.12/site-packages/airflow/models/baseoperator.py", line 406, in wrapper
    return func(self, *args, **kwargs)
           ^^^^^^^^^^^^^^^^^^^^^^^^^^^
  File "/home/airflow/.local/lib/python3.12/site-packages/airflow/operators/python.py", line 238, in execute
    return_value = self.execute_callable()
                   ^^^^^^^^^^^^^^^^^^^^^^^
  File "/home/airflow/.local/lib/python3.12/site-packages/airflow/operators/python.py", line 256, in execute_callable
    return runner.run(*self.op_args, **self.op_kwargs)
           ^^^^^^^^^^^^^^^^^^^^^^^^^^^^^^^^^^^^^^^^^^^
  File "/home/airflow/.local/lib/python3.12/site-packages/airflow/utils/operator_helpers.py", line 252, in run
    return self.func(*args, **kwargs)
           ^^^^^^^^^^^^^^^^^^^^^^^^^^
  File "/opt/airflow/dags/nba_data_pipeline.py", line 57, in run_data_ingestion
    ).execute(context=kwargs)
      ^^^^^^^^^^^^^^^^^^^^^^^
  File "/home/airflow/.local/lib/python3.12/site-packages/airflow/models/baseoperator.py", line 406, in wrapper
    return func(self, *args, **kwargs)
           ^^^^^^^^^^^^^^^^^^^^^^^^^^^
  File "/home/airflow/.local/lib/python3.12/site-packages/airflow/providers/docker/operators/docker.py", line 513, in execute
    return self._run_image()
           ^^^^^^^^^^^^^^^^^
  File "/home/airflow/.local/lib/python3.12/site-packages/airflow/providers/docker/operators/docker.py", line 384, in _run_image
    return self._run_image_with_mounts(self.mounts, add_tmp_variable=False)
           ^^^^^^^^^^^^^^^^^^^^^^^^^^^^^^^^^^^^^^^^^^^^^^^^^^^^^^^^^^^^^^^^
  File "/home/airflow/.local/lib/python3.12/site-packages/airflow/providers/docker/operators/docker.py", line 464, in _run_image_with_mounts
    self.cli.remove_container(self.container["Id"])
  File "/home/airflow/.local/lib/python3.12/site-packages/docker/utils/decorators.py", line 19, in wrapped
    return f(self, resource_id, *args, **kwargs)
           ^^^^^^^^^^^^^^^^^^^^^^^^^^^^^^^^^^^^^
  File "/home/airflow/.local/lib/python3.12/site-packages/docker/api/container.py", line 1037, in remove_container
    self._raise_for_status(res)
  File "/home/airflow/.local/lib/python3.12/site-packages/docker/api/client.py", line 277, in _raise_for_status
    raise create_api_error_from_http_exception(e) from e
          ^^^^^^^^^^^^^^^^^^^^^^^^^^^^^^^^^^^^^^^
  File "/home/airflow/.local/lib/python3.12/site-packages/docker/errors.py", line 39, in create_api_error_from_http_exception
    raise cls(e, response=response, explanation=explanation) from e
docker.errors.APIError: 409 Client Error for http+docker://localhost/v1.47/containers/62f76751ea9de4f38287c205a5536961c2166a0aaf0fa32946e7ed04477ecd60?v=False&link=False&force=False: Conflict ("cannot remove container "/data_ingestion": container is running: stop the container before removing or force remove")
[2024-09-19T08:19:21.034+0000] {process_utils.py:80} INFO - Process psutil.Process(pid=373, status='terminated', exitcode=1, started='08:19:10') (373) terminated with exit code 1
