[2024-09-19T00:47:21.183+0000] {local_task_job_runner.py:123} INFO - ::group::Pre task execution logs
[2024-09-19T00:47:21.201+0000] {taskinstance.py:2612} INFO - Dependencies all met for dep_context=non-requeueable deps ti=<TaskInstance: nba_data_pipeline.run_data_processing manual__2024-09-19T00:46:40.253456+00:00 [queued]>
[2024-09-19T00:47:21.211+0000] {taskinstance.py:2612} INFO - Dependencies all met for dep_context=requeueable deps ti=<TaskInstance: nba_data_pipeline.run_data_processing manual__2024-09-19T00:46:40.253456+00:00 [queued]>
[2024-09-19T00:47:21.211+0000] {taskinstance.py:2865} INFO - Starting attempt 1 of 2
[2024-09-19T00:47:21.226+0000] {taskinstance.py:2888} INFO - Executing <Task(DockerOperator): run_data_processing> on 2024-09-19 00:46:40.253456+00:00
[2024-09-19T00:47:21.233+0000] {standard_task_runner.py:104} INFO - Running: ['airflow', 'tasks', 'run', 'nba_data_pipeline', 'run_data_processing', 'manual__2024-09-19T00:46:40.253456+00:00', '--job-id', '9', '--raw', '--subdir', 'DAGS_FOLDER/nba_data_pipeline.py', '--cfg-path', '/tmp/tmperq1dbi3']
[2024-09-19T00:47:21.236+0000] {standard_task_runner.py:105} INFO - Job 9: Subtask run_data_processing
[2024-09-19T00:47:21.238+0000] {logging_mixin.py:190} WARNING - /home/airflow/.local/lib/python3.12/site-packages/airflow/task/task_runner/standard_task_runner.py:70 DeprecationWarning: This process (pid=286) is multi-threaded, use of fork() may lead to deadlocks in the child.
[2024-09-19T00:47:21.238+0000] {standard_task_runner.py:72} INFO - Started process 287 to run task
[2024-09-19T00:47:21.285+0000] {task_command.py:467} INFO - Running <TaskInstance: nba_data_pipeline.run_data_processing manual__2024-09-19T00:46:40.253456+00:00 [running]> on host 60f4d263d5b1
[2024-09-19T00:47:21.389+0000] {taskinstance.py:3131} INFO - Exporting env vars: AIRFLOW_CTX_DAG_OWNER='airflow' AIRFLOW_CTX_DAG_ID='nba_data_pipeline' AIRFLOW_CTX_TASK_ID='run_data_processing' AIRFLOW_CTX_EXECUTION_DATE='2024-09-19T00:46:40.253456+00:00' AIRFLOW_CTX_TRY_NUMBER='1' AIRFLOW_CTX_DAG_RUN_ID='manual__2024-09-19T00:46:40.253456+00:00'
[2024-09-19T00:47:21.390+0000] {taskinstance.py:731} INFO - ::endgroup::
[2024-09-19T00:47:21.420+0000] {docker.py:367} INFO - Starting docker container from image us-west1-docker.pkg.dev/nba-fantasy-ml/nba-data-pipeline-repo/data-processing:latest
[2024-09-19T00:47:21.429+0000] {docker.py:375} WARNING - Using remote engine or docker-in-docker and mounting temporary volume from host is not supported. Falling back to `mount_tmp_dir=False` mode. You can set `mount_tmp_dir` parameter to False to disable mounting and remove the warning
[2024-09-19T00:47:22.245+0000] {docker.py:438} INFO - 2024-09-19 00:47:22,243 - WARNING - Retrying (Retry(total=4, connect=None, read=None, redirect=None, status=None)) after connection broken by 'NameResolutionError("<urllib3.connection.HTTPConnection object at 0x7fbcbf52a2f0>: Failed to resolve 'minio' ([Errno -2] Name or service not known)")': /nba-raw-data?location=
[2024-09-19T00:47:22.650+0000] {docker.py:438} INFO - 2024-09-19 00:47:22,648 - WARNING - Retrying (Retry(total=3, connect=None, read=None, redirect=None, status=None)) after connection broken by 'NameResolutionError("<urllib3.connection.HTTPConnection object at 0x7fbcbf52a620>: Failed to resolve 'minio' ([Errno -2] Name or service not known)")': /nba-raw-data?location=
[2024-09-19T00:47:23.456+0000] {docker.py:438} INFO - 2024-09-19 00:47:23,455 - WARNING - Retrying (Retry(total=2, connect=None, read=None, redirect=None, status=None)) after connection broken by 'NameResolutionError("<urllib3.connection.HTTPConnection object at 0x7fbcbf52ab30>: Failed to resolve 'minio' ([Errno -2] Name or service not known)")': /nba-raw-data?location=
[2024-09-19T00:47:25.064+0000] {docker.py:438} INFO - 2024-09-19 00:47:25,062 - WARNING - Retrying (Retry(total=1, connect=None, read=None, redirect=None, status=None)) after connection broken by 'NameResolutionError("<urllib3.connection.HTTPConnection object at 0x7fbcbf52ad40>: Failed to resolve 'minio' ([Errno -2] Name or service not known)")': /nba-raw-data?location=
[2024-09-19T00:47:28.274+0000] {docker.py:438} INFO - 2024-09-19 00:47:28,272 - WARNING - Retrying (Retry(total=0, connect=None, read=None, redirect=None, status=None)) after connection broken by 'NameResolutionError("<urllib3.connection.HTTPConnection object at 0x7fbcbf52aef0>: Failed to resolve 'minio' ([Errno -2] Name or service not known)")': /nba-raw-data?location=
[2024-09-19T00:47:28.279+0000] {docker.py:438} INFO - 2024-09-19 00:47:28,277 - ERROR - Error in data processing: HTTPConnectionPool(host='minio', port=9000): Max retries exceeded with url: /nba-raw-data?location= (Caused by NameResolutionError("<urllib3.connection.HTTPConnection object at 0x7fbcbf52b0a0>: Failed to resolve 'minio' ([Errno -2] Name or service not known)"))
[2024-09-19T00:47:28.530+0000] {taskinstance.py:340} INFO - ::group::Post task execution logs
[2024-09-19T00:47:28.531+0000] {taskinstance.py:352} INFO - Marking task as SUCCESS. dag_id=nba_data_pipeline, task_id=run_data_processing, run_id=manual__2024-09-19T00:46:40.253456+00:00, execution_date=20240919T004640, start_date=20240919T004721, end_date=20240919T004728
[2024-09-19T00:47:28.585+0000] {local_task_job_runner.py:266} INFO - Task exited with return code 0
[2024-09-19T00:47:28.604+0000] {taskinstance.py:3900} INFO - 0 downstream tasks scheduled from follow-on schedule check
[2024-09-19T00:47:28.606+0000] {local_task_job_runner.py:245} INFO - ::endgroup::
