[2024-09-19T08:59:34.630+0000] {local_task_job_runner.py:123} INFO - ::group::Pre task execution logs
[2024-09-19T08:59:34.651+0000] {taskinstance.py:2612} INFO - Dependencies all met for dep_context=non-requeueable deps ti=<TaskInstance: nba_data_pipeline.run_data_ingestion manual__2024-09-19T08:59:33.309495+00:00 [queued]>
[2024-09-19T08:59:34.661+0000] {taskinstance.py:2612} INFO - Dependencies all met for dep_context=requeueable deps ti=<TaskInstance: nba_data_pipeline.run_data_ingestion manual__2024-09-19T08:59:33.309495+00:00 [queued]>
[2024-09-19T08:59:34.661+0000] {taskinstance.py:2865} INFO - Starting attempt 1 of 4
[2024-09-19T08:59:34.677+0000] {taskinstance.py:2888} INFO - Executing <Task(DockerOperator): run_data_ingestion> on 2024-09-19 08:59:33.309495+00:00
[2024-09-19T08:59:34.685+0000] {standard_task_runner.py:104} INFO - Running: ['airflow', 'tasks', 'run', 'nba_data_pipeline', 'run_data_ingestion', 'manual__2024-09-19T08:59:33.309495+00:00', '--job-id', '3', '--raw', '--subdir', 'DAGS_FOLDER/nba_data_pipeline.py', '--cfg-path', '/tmp/tmpa117tvs_']
[2024-09-19T08:59:34.688+0000] {standard_task_runner.py:105} INFO - Job 3: Subtask run_data_ingestion
[2024-09-19T08:59:34.690+0000] {logging_mixin.py:190} WARNING - /home/airflow/.local/lib/python3.12/site-packages/airflow/task/task_runner/standard_task_runner.py:70 DeprecationWarning: This process (pid=201) is multi-threaded, use of fork() may lead to deadlocks in the child.
[2024-09-19T08:59:34.692+0000] {standard_task_runner.py:72} INFO - Started process 202 to run task
[2024-09-19T08:59:34.747+0000] {task_command.py:467} INFO - Running <TaskInstance: nba_data_pipeline.run_data_ingestion manual__2024-09-19T08:59:33.309495+00:00 [running]> on host b0a2bec922a8
[2024-09-19T08:59:34.852+0000] {taskinstance.py:3131} INFO - Exporting env vars: AIRFLOW_CTX_DAG_OWNER='airflow' AIRFLOW_CTX_DAG_ID='nba_data_pipeline' AIRFLOW_CTX_TASK_ID='run_data_ingestion' AIRFLOW_CTX_EXECUTION_DATE='2024-09-19T08:59:33.309495+00:00' AIRFLOW_CTX_TRY_NUMBER='1' AIRFLOW_CTX_DAG_RUN_ID='manual__2024-09-19T08:59:33.309495+00:00'
[2024-09-19T08:59:34.853+0000] {taskinstance.py:731} INFO - ::endgroup::
[2024-09-19T08:59:34.884+0000] {docker.py:367} INFO - Starting docker container from image us-west1-docker.pkg.dev/nba-fantasy-ml/nba-data-pipeline-repo/data-ingestion:latest
[2024-09-19T08:59:34.894+0000] {docker.py:375} WARNING - Using remote engine or docker-in-docker and mounting temporary volume from host is not supported. Falling back to `mount_tmp_dir=False` mode. You can set `mount_tmp_dir` parameter to False to disable mounting and remove the warning
[2024-09-19T09:01:02.871+0000] {docker.py:438} INFO - Processing batch 1/1
[2024-09-19T09:01:02.872+0000] {docker.py:438} INFO - Scraping box score: https://www.basketball-reference.com/boxscores/202310240DEN.html for game date 2023-10-24
[2024-09-19T09:01:02.873+0000] {docker.py:438} INFO - Scraping box score: https://www.basketball-reference.com/boxscores/202310240GSW.html for game date 2023-10-24
[2024-09-19T09:01:02.873+0000] {docker.py:438} INFO - Scraping box score: https://www.basketball-reference.com/boxscores/202310250ORL.html for game date 2023-10-25
[2024-09-19T09:01:02.873+0000] {docker.py:438} INFO - Scraping box score: https://www.basketball-reference.com/boxscores/202310250NYK.html for game date 2023-10-25
[2024-09-19T09:01:02.874+0000] {docker.py:438} INFO - Scraping box score: https://www.basketball-reference.com/boxscores/202310250IND.html for game date 2023-10-25
[2024-09-19T09:01:02.874+0000] {docker.py:438} INFO - Scraping box score: https://www.basketball-reference.com/boxscores/202310250CHO.html for game date 2023-10-25
[2024-09-19T09:01:02.875+0000] {docker.py:438} INFO - Scraping box score: https://www.basketball-reference.com/boxscores/202310250MIA.html for game date 2023-10-25
[2024-09-19T09:01:02.875+0000] {docker.py:438} INFO - Scraping box score: https://www.basketball-reference.com/boxscores/202310250TOR.html for game date 2023-10-25
[2024-09-19T09:01:02.876+0000] {docker.py:438} INFO - Scraping box score: https://www.basketball-reference.com/boxscores/202310250BRK.html for game date 2023-10-25
[2024-09-19T09:01:02.876+0000] {docker.py:438} INFO - Scraping box score: https://www.basketball-reference.com/boxscores/202310250MEM.html for game date 2023-10-25
[2024-09-19T09:01:02.877+0000] {docker.py:438} INFO - Skipping incomplete data for ja morant
[2024-09-19T09:01:02.877+0000] {docker.py:438} INFO - Scraping box score: https://www.basketball-reference.com/boxscores/202310250CHI.html for game date 2023-10-25
[2024-09-19T09:01:02.878+0000] {docker.py:438} INFO - Scraping box score: https://www.basketball-reference.com/boxscores/202310250UTA.html for game date 2023-10-25
[2024-09-19T09:01:02.878+0000] {docker.py:438} INFO - Scraping box score: https://www.basketball-reference.com/boxscores/202310250SAS.html for game date 2023-10-25
[2024-09-19T09:01:02.878+0000] {docker.py:438} INFO - Skipping incomplete data for devonte' graham
[2024-09-19T09:01:02.879+0000] {docker.py:438} INFO - Scraping box score: https://www.basketball-reference.com/boxscores/202310250LAC.html for game date 2023-10-25
[2024-09-19T09:01:02.879+0000] {docker.py:438} INFO - Failed to upload player_box_scores/2023-24/nba_player_stats_2023-24_2023-10-24_to_2023-10-25_2024-09-19_09-01-02.csv: 'bytes' object has no attribute 'read'
[2024-09-19T09:01:02.879+0000] {docker.py:438} INFO - 2024-09-19 09:01:02,870 - ERROR - Error uploading data to MinIO: 'bytes' object has no attribute 'read'
[2024-09-19T09:01:03.146+0000] {taskinstance.py:3310} ERROR - Task failed with exception
Traceback (most recent call last):
  File "/home/airflow/.local/lib/python3.12/site-packages/docker/api/client.py", line 275, in _raise_for_status
    response.raise_for_status()
  File "/home/airflow/.local/lib/python3.12/site-packages/requests/models.py", line 1024, in raise_for_status
    raise HTTPError(http_error_msg, response=self)
requests.exceptions.HTTPError: 400 Client Error: Bad Request for url: http+docker://localhost/v1.47/containers/create

The above exception was the direct cause of the following exception:

Traceback (most recent call last):
  File "/home/airflow/.local/lib/python3.12/site-packages/airflow/providers/docker/operators/docker.py", line 372, in _run_image
    return self._run_image_with_mounts([*self.mounts, tmp_mount], add_tmp_variable=True)
           ^^^^^^^^^^^^^^^^^^^^^^^^^^^^^^^^^^^^^^^^^^^^^^^^^^^^^^^^^^^^^^^^^^^^^^^^^^^^^
  File "/home/airflow/.local/lib/python3.12/site-packages/airflow/providers/docker/operators/docker.py", line 399, in _run_image_with_mounts
    self.container = self.cli.create_container(
                     ^^^^^^^^^^^^^^^^^^^^^^^^^^
  File "/home/airflow/.local/lib/python3.12/site-packages/docker/api/container.py", line 440, in create_container
    return self.create_container_from_config(config, name, platform)
           ^^^^^^^^^^^^^^^^^^^^^^^^^^^^^^^^^^^^^^^^^^^^^^^^^^^^^^^^^
  File "/home/airflow/.local/lib/python3.12/site-packages/docker/api/container.py", line 457, in create_container_from_config
    return self._result(res, True)
           ^^^^^^^^^^^^^^^^^^^^^^^
  File "/home/airflow/.local/lib/python3.12/site-packages/docker/api/client.py", line 281, in _result
    self._raise_for_status(response)
  File "/home/airflow/.local/lib/python3.12/site-packages/docker/api/client.py", line 277, in _raise_for_status
    raise create_api_error_from_http_exception(e) from e
          ^^^^^^^^^^^^^^^^^^^^^^^^^^^^^^^^^^^^^^^
  File "/home/airflow/.local/lib/python3.12/site-packages/docker/errors.py", line 39, in create_api_error_from_http_exception
    raise cls(e, response=response, explanation=explanation) from e
docker.errors.APIError: 400 Client Error for http+docker://localhost/v1.47/containers/create: Bad Request ("invalid mount config for type "bind": bind source path does not exist: /host_mnt/private/tmp/airflowtmpc3z70ncr")

During handling of the above exception, another exception occurred:

Traceback (most recent call last):
  File "/home/airflow/.local/lib/python3.12/site-packages/airflow/models/taskinstance.py", line 767, in _execute_task
    result = _execute_callable(context=context, **execute_callable_kwargs)
             ^^^^^^^^^^^^^^^^^^^^^^^^^^^^^^^^^^^^^^^^^^^^^^^^^^^^^^^^^^^^^
  File "/home/airflow/.local/lib/python3.12/site-packages/airflow/models/taskinstance.py", line 733, in _execute_callable
    return ExecutionCallableRunner(
           ^^^^^^^^^^^^^^^^^^^^^^^^
  File "/home/airflow/.local/lib/python3.12/site-packages/airflow/utils/operator_helpers.py", line 252, in run
    return self.func(*args, **kwargs)
           ^^^^^^^^^^^^^^^^^^^^^^^^^^
  File "/home/airflow/.local/lib/python3.12/site-packages/airflow/models/baseoperator.py", line 406, in wrapper
    return func(self, *args, **kwargs)
           ^^^^^^^^^^^^^^^^^^^^^^^^^^^
  File "/home/airflow/.local/lib/python3.12/site-packages/airflow/providers/docker/operators/docker.py", line 513, in execute
    return self._run_image()
           ^^^^^^^^^^^^^^^^^
  File "/home/airflow/.local/lib/python3.12/site-packages/airflow/providers/docker/operators/docker.py", line 381, in _run_image
    return self._run_image_with_mounts(self.mounts, add_tmp_variable=False)
           ^^^^^^^^^^^^^^^^^^^^^^^^^^^^^^^^^^^^^^^^^^^^^^^^^^^^^^^^^^^^^^^^
  File "/home/airflow/.local/lib/python3.12/site-packages/airflow/providers/docker/operators/docker.py", line 446, in _run_image_with_mounts
    raise DockerContainerFailedException(f"Docker container failed: {result!r}", logs=log_lines)
airflow.providers.docker.exceptions.DockerContainerFailedException: Docker container failed: {'StatusCode': 1}
[2024-09-19T09:01:03.156+0000] {taskinstance.py:1225} INFO - Marking task as UP_FOR_RETRY. dag_id=nba_data_pipeline, task_id=run_data_ingestion, run_id=manual__2024-09-19T08:59:33.309495+00:00, execution_date=20240919T085933, start_date=20240919T085934, end_date=20240919T090103
[2024-09-19T09:01:03.171+0000] {taskinstance.py:340} INFO - ::group::Post task execution logs
[2024-09-19T09:01:03.172+0000] {standard_task_runner.py:124} ERROR - Failed to execute job 3 for task run_data_ingestion (Docker container failed: {'StatusCode': 1}; 202)
Traceback (most recent call last):
  File "/home/airflow/.local/lib/python3.12/site-packages/docker/api/client.py", line 275, in _raise_for_status
    response.raise_for_status()
  File "/home/airflow/.local/lib/python3.12/site-packages/requests/models.py", line 1024, in raise_for_status
    raise HTTPError(http_error_msg, response=self)
requests.exceptions.HTTPError: 400 Client Error: Bad Request for url: http+docker://localhost/v1.47/containers/create

The above exception was the direct cause of the following exception:

Traceback (most recent call last):
  File "/home/airflow/.local/lib/python3.12/site-packages/airflow/providers/docker/operators/docker.py", line 372, in _run_image
    return self._run_image_with_mounts([*self.mounts, tmp_mount], add_tmp_variable=True)
           ^^^^^^^^^^^^^^^^^^^^^^^^^^^^^^^^^^^^^^^^^^^^^^^^^^^^^^^^^^^^^^^^^^^^^^^^^^^^^
  File "/home/airflow/.local/lib/python3.12/site-packages/airflow/providers/docker/operators/docker.py", line 399, in _run_image_with_mounts
    self.container = self.cli.create_container(
                     ^^^^^^^^^^^^^^^^^^^^^^^^^^
  File "/home/airflow/.local/lib/python3.12/site-packages/docker/api/container.py", line 440, in create_container
    return self.create_container_from_config(config, name, platform)
           ^^^^^^^^^^^^^^^^^^^^^^^^^^^^^^^^^^^^^^^^^^^^^^^^^^^^^^^^^
  File "/home/airflow/.local/lib/python3.12/site-packages/docker/api/container.py", line 457, in create_container_from_config
    return self._result(res, True)
           ^^^^^^^^^^^^^^^^^^^^^^^
  File "/home/airflow/.local/lib/python3.12/site-packages/docker/api/client.py", line 281, in _result
    self._raise_for_status(response)
  File "/home/airflow/.local/lib/python3.12/site-packages/docker/api/client.py", line 277, in _raise_for_status
    raise create_api_error_from_http_exception(e) from e
          ^^^^^^^^^^^^^^^^^^^^^^^^^^^^^^^^^^^^^^^
  File "/home/airflow/.local/lib/python3.12/site-packages/docker/errors.py", line 39, in create_api_error_from_http_exception
    raise cls(e, response=response, explanation=explanation) from e
docker.errors.APIError: 400 Client Error for http+docker://localhost/v1.47/containers/create: Bad Request ("invalid mount config for type "bind": bind source path does not exist: /host_mnt/private/tmp/airflowtmpc3z70ncr")

During handling of the above exception, another exception occurred:

Traceback (most recent call last):
  File "/home/airflow/.local/lib/python3.12/site-packages/airflow/task/task_runner/standard_task_runner.py", line 117, in _start_by_fork
    ret = args.func(args, dag=self.dag)
          ^^^^^^^^^^^^^^^^^^^^^^^^^^^^^
  File "/home/airflow/.local/lib/python3.12/site-packages/airflow/cli/cli_config.py", line 49, in command
    return func(*args, **kwargs)
           ^^^^^^^^^^^^^^^^^^^^^
  File "/home/airflow/.local/lib/python3.12/site-packages/airflow/utils/cli.py", line 115, in wrapper
    return f(*args, **kwargs)
           ^^^^^^^^^^^^^^^^^^
  File "/home/airflow/.local/lib/python3.12/site-packages/airflow/cli/commands/task_command.py", line 483, in task_run
    task_return_code = _run_task_by_selected_method(args, _dag, ti)
                       ^^^^^^^^^^^^^^^^^^^^^^^^^^^^^^^^^^^^^^^^^^^^
  File "/home/airflow/.local/lib/python3.12/site-packages/airflow/cli/commands/task_command.py", line 256, in _run_task_by_selected_method
    return _run_raw_task(args, ti)
           ^^^^^^^^^^^^^^^^^^^^^^^
  File "/home/airflow/.local/lib/python3.12/site-packages/airflow/cli/commands/task_command.py", line 341, in _run_raw_task
    return ti._run_raw_task(
           ^^^^^^^^^^^^^^^^^
  File "/home/airflow/.local/lib/python3.12/site-packages/airflow/utils/session.py", line 97, in wrapper
    return func(*args, session=session, **kwargs)
           ^^^^^^^^^^^^^^^^^^^^^^^^^^^^^^^^^^^^^^
  File "/home/airflow/.local/lib/python3.12/site-packages/airflow/models/taskinstance.py", line 3004, in _run_raw_task
    return _run_raw_task(
           ^^^^^^^^^^^^^^
  File "/home/airflow/.local/lib/python3.12/site-packages/airflow/models/taskinstance.py", line 273, in _run_raw_task
    TaskInstance._execute_task_with_callbacks(
  File "/home/airflow/.local/lib/python3.12/site-packages/airflow/models/taskinstance.py", line 3158, in _execute_task_with_callbacks
    result = self._execute_task(context, task_orig)
             ^^^^^^^^^^^^^^^^^^^^^^^^^^^^^^^^^^^^^^
  File "/home/airflow/.local/lib/python3.12/site-packages/airflow/models/taskinstance.py", line 3182, in _execute_task
    return _execute_task(self, context, task_orig)
           ^^^^^^^^^^^^^^^^^^^^^^^^^^^^^^^^^^^^^^^
  File "/home/airflow/.local/lib/python3.12/site-packages/airflow/models/taskinstance.py", line 767, in _execute_task
    result = _execute_callable(context=context, **execute_callable_kwargs)
             ^^^^^^^^^^^^^^^^^^^^^^^^^^^^^^^^^^^^^^^^^^^^^^^^^^^^^^^^^^^^^
  File "/home/airflow/.local/lib/python3.12/site-packages/airflow/models/taskinstance.py", line 733, in _execute_callable
    return ExecutionCallableRunner(
           ^^^^^^^^^^^^^^^^^^^^^^^^
  File "/home/airflow/.local/lib/python3.12/site-packages/airflow/utils/operator_helpers.py", line 252, in run
    return self.func(*args, **kwargs)
           ^^^^^^^^^^^^^^^^^^^^^^^^^^
  File "/home/airflow/.local/lib/python3.12/site-packages/airflow/models/baseoperator.py", line 406, in wrapper
    return func(self, *args, **kwargs)
           ^^^^^^^^^^^^^^^^^^^^^^^^^^^
  File "/home/airflow/.local/lib/python3.12/site-packages/airflow/providers/docker/operators/docker.py", line 513, in execute
    return self._run_image()
           ^^^^^^^^^^^^^^^^^
  File "/home/airflow/.local/lib/python3.12/site-packages/airflow/providers/docker/operators/docker.py", line 381, in _run_image
    return self._run_image_with_mounts(self.mounts, add_tmp_variable=False)
           ^^^^^^^^^^^^^^^^^^^^^^^^^^^^^^^^^^^^^^^^^^^^^^^^^^^^^^^^^^^^^^^^
  File "/home/airflow/.local/lib/python3.12/site-packages/airflow/providers/docker/operators/docker.py", line 446, in _run_image_with_mounts
    raise DockerContainerFailedException(f"Docker container failed: {result!r}", logs=log_lines)
airflow.providers.docker.exceptions.DockerContainerFailedException: Docker container failed: {'StatusCode': 1}
[2024-09-19T09:01:03.220+0000] {local_task_job_runner.py:266} INFO - Task exited with return code 1
[2024-09-19T09:01:03.242+0000] {taskinstance.py:3900} INFO - 0 downstream tasks scheduled from follow-on schedule check
[2024-09-19T09:01:03.243+0000] {local_task_job_runner.py:245} INFO - ::endgroup::
