[2024-09-18T22:48:20.671+0000] {local_task_job_runner.py:123} INFO - ::group::Pre task execution logs
[2024-09-18T22:48:20.690+0000] {taskinstance.py:2612} INFO - Dependencies all met for dep_context=non-requeueable deps ti=<TaskInstance: nba_data_pipeline.run_data_ingestion scheduled__2024-09-17T00:00:00+00:00 [queued]>
[2024-09-18T22:48:20.700+0000] {taskinstance.py:2612} INFO - Dependencies all met for dep_context=requeueable deps ti=<TaskInstance: nba_data_pipeline.run_data_ingestion scheduled__2024-09-17T00:00:00+00:00 [queued]>
[2024-09-18T22:48:20.700+0000] {taskinstance.py:2865} INFO - Starting attempt 2 of 2
[2024-09-18T22:48:20.714+0000] {taskinstance.py:2888} INFO - Executing <Task(_DockerDecoratedOperator): run_data_ingestion> on 2024-09-17 00:00:00+00:00
[2024-09-18T22:48:20.722+0000] {standard_task_runner.py:104} INFO - Running: ['airflow', 'tasks', 'run', 'nba_data_pipeline', 'run_data_ingestion', 'scheduled__2024-09-17T00:00:00+00:00', '--job-id', '4', '--raw', '--subdir', 'DAGS_FOLDER/nba_data_pipeline.py', '--cfg-path', '/tmp/tmpiamskkgc']
[2024-09-18T22:48:20.725+0000] {standard_task_runner.py:105} INFO - Job 4: Subtask run_data_ingestion
[2024-09-18T22:48:20.727+0000] {logging_mixin.py:190} WARNING - /home/airflow/.local/lib/python3.12/site-packages/airflow/task/task_runner/standard_task_runner.py:70 DeprecationWarning: This process (pid=256) is multi-threaded, use of fork() may lead to deadlocks in the child.
[2024-09-18T22:48:20.728+0000] {standard_task_runner.py:72} INFO - Started process 257 to run task
[2024-09-18T22:48:20.777+0000] {task_command.py:467} INFO - Running <TaskInstance: nba_data_pipeline.run_data_ingestion scheduled__2024-09-17T00:00:00+00:00 [running]> on host ab357b00a8f2
[2024-09-18T22:48:20.841+0000] {abstractoperator.py:778} ERROR - Exception rendering Jinja template for task 'run_data_ingestion', field 'environment'. Template: {'MINIO_ENDPOINT': '{{ conn.minio_default.host }}:{{ conn.minio_default.port }}', 'MINIO_BUCKET_NAME': '{{ var.value.minio_bucket_name }}', 'MINIO_SECURE': '{{ var.value.minio_secure }}', 'MINIO_ROOT_USER': '{{ conn.minio_default.login }}', 'MINIO_ROOT_PASSWORD': '***'}
Traceback (most recent call last):
  File "/home/airflow/.local/lib/python3.12/site-packages/airflow/models/abstractoperator.py", line 770, in _do_render_template_fields
    rendered_content = self.render_template(
                       ^^^^^^^^^^^^^^^^^^^^^
  File "/home/airflow/.local/lib/python3.12/site-packages/airflow/template/templater.py", line 185, in render_template
    return {k: self.render_template(v, context, jinja_env, oids) for k, v in value.items()}
               ^^^^^^^^^^^^^^^^^^^^^^^^^^^^^^^^^^^^^^^^^^^^^^^^^
  File "/home/airflow/.local/lib/python3.12/site-packages/airflow/template/templater.py", line 171, in render_template
    return self._render(template, context)
           ^^^^^^^^^^^^^^^^^^^^^^^^^^^^^^^
  File "/home/airflow/.local/lib/python3.12/site-packages/airflow/models/abstractoperator.py", line 725, in _render
    return super()._render(template, context, dag=dag)
           ^^^^^^^^^^^^^^^^^^^^^^^^^^^^^^^^^^^^^^^^^^^
  File "/home/airflow/.local/lib/python3.12/site-packages/airflow/template/templater.py", line 127, in _render
    return render_template_to_string(template, context)
           ^^^^^^^^^^^^^^^^^^^^^^^^^^^^^^^^^^^^^^^^^^^^
  File "/home/airflow/.local/lib/python3.12/site-packages/airflow/utils/helpers.py", line 301, in render_template_to_string
    return render_template(template, cast(MutableMapping[str, Any], context), native=False)
           ^^^^^^^^^^^^^^^^^^^^^^^^^^^^^^^^^^^^^^^^^^^^^^^^^^^^^^^^^^^^^^^^^^^^^^^^^^^^^^^^
  File "/home/airflow/.local/lib/python3.12/site-packages/airflow/utils/helpers.py", line 296, in render_template
    return "".join(nodes)
           ^^^^^^^^^^^^^^
  File "<template>", line 12, in root
  File "/home/airflow/.local/lib/python3.12/site-packages/jinja2/sandbox.py", line 327, in getattr
    value = getattr(obj, attribute)
            ^^^^^^^^^^^^^^^^^^^^^^^
  File "/home/airflow/.local/lib/python3.12/site-packages/airflow/utils/context.py", line 149, in __getattr__
    self.var = Connection.get_connection_from_secrets(key)
               ^^^^^^^^^^^^^^^^^^^^^^^^^^^^^^^^^^^^^^^^^^^
  File "/home/airflow/.local/lib/python3.12/site-packages/airflow/models/connection.py", line 537, in get_connection_from_secrets
    raise AirflowNotFoundException(f"The conn_id `{conn_id}` isn't defined")
airflow.exceptions.AirflowNotFoundException: The conn_id `minio_default` isn't defined
[2024-09-18T22:48:20.853+0000] {taskinstance.py:3310} ERROR - Task failed with exception
Traceback (most recent call last):
  File "/home/airflow/.local/lib/python3.12/site-packages/airflow/models/taskinstance.py", line 273, in _run_raw_task
    TaskInstance._execute_task_with_callbacks(
  File "/home/airflow/.local/lib/python3.12/site-packages/airflow/models/taskinstance.py", line 3114, in _execute_task_with_callbacks
    task_orig = self.render_templates(context=context, jinja_env=jinja_env)
                ^^^^^^^^^^^^^^^^^^^^^^^^^^^^^^^^^^^^^^^^^^^^^^^^^^^^^^^^^^^
  File "/home/airflow/.local/lib/python3.12/site-packages/airflow/models/taskinstance.py", line 3533, in render_templates
    original_task.render_template_fields(context, jinja_env)
  File "/home/airflow/.local/lib/python3.12/site-packages/airflow/models/baseoperator.py", line 1419, in render_template_fields
    self._do_render_template_fields(self, self.template_fields, context, jinja_env, set())
  File "/home/airflow/.local/lib/python3.12/site-packages/airflow/models/abstractoperator.py", line 770, in _do_render_template_fields
    rendered_content = self.render_template(
                       ^^^^^^^^^^^^^^^^^^^^^
  File "/home/airflow/.local/lib/python3.12/site-packages/airflow/template/templater.py", line 185, in render_template
    return {k: self.render_template(v, context, jinja_env, oids) for k, v in value.items()}
               ^^^^^^^^^^^^^^^^^^^^^^^^^^^^^^^^^^^^^^^^^^^^^^^^^
  File "/home/airflow/.local/lib/python3.12/site-packages/airflow/template/templater.py", line 171, in render_template
    return self._render(template, context)
           ^^^^^^^^^^^^^^^^^^^^^^^^^^^^^^^
  File "/home/airflow/.local/lib/python3.12/site-packages/airflow/models/abstractoperator.py", line 725, in _render
    return super()._render(template, context, dag=dag)
           ^^^^^^^^^^^^^^^^^^^^^^^^^^^^^^^^^^^^^^^^^^^
  File "/home/airflow/.local/lib/python3.12/site-packages/airflow/template/templater.py", line 127, in _render
    return render_template_to_string(template, context)
           ^^^^^^^^^^^^^^^^^^^^^^^^^^^^^^^^^^^^^^^^^^^^
  File "/home/airflow/.local/lib/python3.12/site-packages/airflow/utils/helpers.py", line 301, in render_template_to_string
    return render_template(template, cast(MutableMapping[str, Any], context), native=False)
           ^^^^^^^^^^^^^^^^^^^^^^^^^^^^^^^^^^^^^^^^^^^^^^^^^^^^^^^^^^^^^^^^^^^^^^^^^^^^^^^^
  File "/home/airflow/.local/lib/python3.12/site-packages/airflow/utils/helpers.py", line 296, in render_template
    return "".join(nodes)
           ^^^^^^^^^^^^^^
  File "<template>", line 12, in root
  File "/home/airflow/.local/lib/python3.12/site-packages/jinja2/sandbox.py", line 327, in getattr
    value = getattr(obj, attribute)
            ^^^^^^^^^^^^^^^^^^^^^^^
  File "/home/airflow/.local/lib/python3.12/site-packages/airflow/utils/context.py", line 149, in __getattr__
    self.var = Connection.get_connection_from_secrets(key)
               ^^^^^^^^^^^^^^^^^^^^^^^^^^^^^^^^^^^^^^^^^^^
  File "/home/airflow/.local/lib/python3.12/site-packages/airflow/models/connection.py", line 537, in get_connection_from_secrets
    raise AirflowNotFoundException(f"The conn_id `{conn_id}` isn't defined")
airflow.exceptions.AirflowNotFoundException: The conn_id `minio_default` isn't defined
[2024-09-18T22:48:20.858+0000] {taskinstance.py:1225} INFO - Marking task as FAILED. dag_id=nba_data_pipeline, task_id=run_data_ingestion, run_id=scheduled__2024-09-17T00:00:00+00:00, execution_date=20240917T000000, start_date=20240918T224820, end_date=20240918T224820
[2024-09-18T22:48:20.869+0000] {taskinstance.py:340} INFO - ::group::Post task execution logs
[2024-09-18T22:48:20.870+0000] {standard_task_runner.py:124} ERROR - Failed to execute job 4 for task run_data_ingestion (The conn_id `minio_default` isn't defined; 257)
Traceback (most recent call last):
  File "/home/airflow/.local/lib/python3.12/site-packages/airflow/task/task_runner/standard_task_runner.py", line 117, in _start_by_fork
    ret = args.func(args, dag=self.dag)
          ^^^^^^^^^^^^^^^^^^^^^^^^^^^^^
  File "/home/airflow/.local/lib/python3.12/site-packages/airflow/cli/cli_config.py", line 49, in command
    return func(*args, **kwargs)
           ^^^^^^^^^^^^^^^^^^^^^
  File "/home/airflow/.local/lib/python3.12/site-packages/airflow/utils/cli.py", line 115, in wrapper
    return f(*args, **kwargs)
           ^^^^^^^^^^^^^^^^^^
  File "/home/airflow/.local/lib/python3.12/site-packages/airflow/cli/commands/task_command.py", line 483, in task_run
    task_return_code = _run_task_by_selected_method(args, _dag, ti)
                       ^^^^^^^^^^^^^^^^^^^^^^^^^^^^^^^^^^^^^^^^^^^^
  File "/home/airflow/.local/lib/python3.12/site-packages/airflow/cli/commands/task_command.py", line 256, in _run_task_by_selected_method
    return _run_raw_task(args, ti)
           ^^^^^^^^^^^^^^^^^^^^^^^
  File "/home/airflow/.local/lib/python3.12/site-packages/airflow/cli/commands/task_command.py", line 341, in _run_raw_task
    return ti._run_raw_task(
           ^^^^^^^^^^^^^^^^^
  File "/home/airflow/.local/lib/python3.12/site-packages/airflow/utils/session.py", line 97, in wrapper
    return func(*args, session=session, **kwargs)
           ^^^^^^^^^^^^^^^^^^^^^^^^^^^^^^^^^^^^^^
  File "/home/airflow/.local/lib/python3.12/site-packages/airflow/models/taskinstance.py", line 3004, in _run_raw_task
    return _run_raw_task(
           ^^^^^^^^^^^^^^
  File "/home/airflow/.local/lib/python3.12/site-packages/airflow/models/taskinstance.py", line 273, in _run_raw_task
    TaskInstance._execute_task_with_callbacks(
  File "/home/airflow/.local/lib/python3.12/site-packages/airflow/models/taskinstance.py", line 3114, in _execute_task_with_callbacks
    task_orig = self.render_templates(context=context, jinja_env=jinja_env)
                ^^^^^^^^^^^^^^^^^^^^^^^^^^^^^^^^^^^^^^^^^^^^^^^^^^^^^^^^^^^
  File "/home/airflow/.local/lib/python3.12/site-packages/airflow/models/taskinstance.py", line 3533, in render_templates
    original_task.render_template_fields(context, jinja_env)
  File "/home/airflow/.local/lib/python3.12/site-packages/airflow/models/baseoperator.py", line 1419, in render_template_fields
    self._do_render_template_fields(self, self.template_fields, context, jinja_env, set())
  File "/home/airflow/.local/lib/python3.12/site-packages/airflow/models/abstractoperator.py", line 770, in _do_render_template_fields
    rendered_content = self.render_template(
                       ^^^^^^^^^^^^^^^^^^^^^
  File "/home/airflow/.local/lib/python3.12/site-packages/airflow/template/templater.py", line 185, in render_template
    return {k: self.render_template(v, context, jinja_env, oids) for k, v in value.items()}
               ^^^^^^^^^^^^^^^^^^^^^^^^^^^^^^^^^^^^^^^^^^^^^^^^^
  File "/home/airflow/.local/lib/python3.12/site-packages/airflow/template/templater.py", line 171, in render_template
    return self._render(template, context)
           ^^^^^^^^^^^^^^^^^^^^^^^^^^^^^^^
  File "/home/airflow/.local/lib/python3.12/site-packages/airflow/models/abstractoperator.py", line 725, in _render
    return super()._render(template, context, dag=dag)
           ^^^^^^^^^^^^^^^^^^^^^^^^^^^^^^^^^^^^^^^^^^^
  File "/home/airflow/.local/lib/python3.12/site-packages/airflow/template/templater.py", line 127, in _render
    return render_template_to_string(template, context)
           ^^^^^^^^^^^^^^^^^^^^^^^^^^^^^^^^^^^^^^^^^^^^
  File "/home/airflow/.local/lib/python3.12/site-packages/airflow/utils/helpers.py", line 301, in render_template_to_string
    return render_template(template, cast(MutableMapping[str, Any], context), native=False)
           ^^^^^^^^^^^^^^^^^^^^^^^^^^^^^^^^^^^^^^^^^^^^^^^^^^^^^^^^^^^^^^^^^^^^^^^^^^^^^^^^
  File "/home/airflow/.local/lib/python3.12/site-packages/airflow/utils/helpers.py", line 296, in render_template
    return "".join(nodes)
           ^^^^^^^^^^^^^^
  File "<template>", line 12, in root
  File "/home/airflow/.local/lib/python3.12/site-packages/jinja2/sandbox.py", line 327, in getattr
    value = getattr(obj, attribute)
            ^^^^^^^^^^^^^^^^^^^^^^^
  File "/home/airflow/.local/lib/python3.12/site-packages/airflow/utils/context.py", line 149, in __getattr__
    self.var = Connection.get_connection_from_secrets(key)
               ^^^^^^^^^^^^^^^^^^^^^^^^^^^^^^^^^^^^^^^^^^^
  File "/home/airflow/.local/lib/python3.12/site-packages/airflow/models/connection.py", line 537, in get_connection_from_secrets
    raise AirflowNotFoundException(f"The conn_id `{conn_id}` isn't defined")
airflow.exceptions.AirflowNotFoundException: The conn_id `minio_default` isn't defined
[2024-09-18T22:48:20.912+0000] {local_task_job_runner.py:266} INFO - Task exited with return code 1
[2024-09-18T22:48:20.939+0000] {taskinstance.py:3900} INFO - 0 downstream tasks scheduled from follow-on schedule check
[2024-09-18T22:48:20.943+0000] {local_task_job_runner.py:245} INFO - ::endgroup::
[2024-09-18T23:09:47.727+0000] {local_task_job_runner.py:123} INFO - ::group::Pre task execution logs
[2024-09-18T23:09:47.750+0000] {taskinstance.py:2612} INFO - Dependencies all met for dep_context=non-requeueable deps ti=<TaskInstance: nba_data_pipeline.run_data_ingestion scheduled__2024-09-17T00:00:00+00:00 [queued]>
[2024-09-18T23:09:47.760+0000] {taskinstance.py:2612} INFO - Dependencies all met for dep_context=requeueable deps ti=<TaskInstance: nba_data_pipeline.run_data_ingestion scheduled__2024-09-17T00:00:00+00:00 [queued]>
[2024-09-18T23:09:47.761+0000] {taskinstance.py:2865} INFO - Starting attempt 2 of 2
[2024-09-18T23:09:47.779+0000] {taskinstance.py:2888} INFO - Executing <Task(_DockerDecoratedOperator): run_data_ingestion> on 2024-09-17 00:00:00+00:00
[2024-09-18T23:09:47.788+0000] {standard_task_runner.py:104} INFO - Running: ['airflow', 'tasks', 'run', 'nba_data_pipeline', 'run_data_ingestion', 'scheduled__2024-09-17T00:00:00+00:00', '--job-id', '4', '--raw', '--subdir', 'DAGS_FOLDER/nba_data_pipeline.py', '--cfg-path', '/tmp/tmpe7hglbum']
[2024-09-18T23:09:47.791+0000] {standard_task_runner.py:105} INFO - Job 4: Subtask run_data_ingestion
[2024-09-18T23:09:47.793+0000] {logging_mixin.py:190} WARNING - /home/airflow/.local/lib/python3.12/site-packages/airflow/task/task_runner/standard_task_runner.py:70 DeprecationWarning: This process (pid=266) is multi-threaded, use of fork() may lead to deadlocks in the child.
[2024-09-18T23:09:47.795+0000] {standard_task_runner.py:72} INFO - Started process 268 to run task
[2024-09-18T23:09:47.854+0000] {task_command.py:467} INFO - Running <TaskInstance: nba_data_pipeline.run_data_ingestion scheduled__2024-09-17T00:00:00+00:00 [running]> on host a2e8cfe96f19
[2024-09-18T23:09:47.949+0000] {taskinstance.py:3131} INFO - Exporting env vars: AIRFLOW_CTX_DAG_OWNER='airflow' AIRFLOW_CTX_DAG_ID='nba_data_pipeline' AIRFLOW_CTX_TASK_ID='run_data_ingestion' AIRFLOW_CTX_EXECUTION_DATE='2024-09-17T00:00:00+00:00' AIRFLOW_CTX_TRY_NUMBER='2' AIRFLOW_CTX_DAG_RUN_ID='scheduled__2024-09-17T00:00:00+00:00'
[2024-09-18T23:09:47.950+0000] {taskinstance.py:731} INFO - ::endgroup::
[2024-09-18T23:09:47.970+0000] {docker.py:157} ERROR - Failed to establish connection to Docker host unix://var/run/docker.sock: Error while fetching server API version: ('Connection aborted.', FileNotFoundError(2, 'No such file or directory'))
[2024-09-18T23:09:47.984+0000] {taskinstance.py:3310} ERROR - Task failed with exception
Traceback (most recent call last):
  File "/home/airflow/.local/lib/python3.12/site-packages/airflow/models/taskinstance.py", line 767, in _execute_task
    result = _execute_callable(context=context, **execute_callable_kwargs)
             ^^^^^^^^^^^^^^^^^^^^^^^^^^^^^^^^^^^^^^^^^^^^^^^^^^^^^^^^^^^^^
  File "/home/airflow/.local/lib/python3.12/site-packages/airflow/models/taskinstance.py", line 733, in _execute_callable
    return ExecutionCallableRunner(
           ^^^^^^^^^^^^^^^^^^^^^^^^
  File "/home/airflow/.local/lib/python3.12/site-packages/airflow/utils/operator_helpers.py", line 252, in run
    return self.func(*args, **kwargs)
           ^^^^^^^^^^^^^^^^^^^^^^^^^^
  File "/home/airflow/.local/lib/python3.12/site-packages/airflow/models/baseoperator.py", line 406, in wrapper
    return func(self, *args, **kwargs)
           ^^^^^^^^^^^^^^^^^^^^^^^^^^^
  File "/home/airflow/.local/lib/python3.12/site-packages/airflow/providers/docker/decorators/docker.py", line 199, in execute
    return super().execute(context)
           ^^^^^^^^^^^^^^^^^^^^^^^^
  File "/home/airflow/.local/lib/python3.12/site-packages/airflow/models/baseoperator.py", line 406, in wrapper
    return func(self, *args, **kwargs)
           ^^^^^^^^^^^^^^^^^^^^^^^^^^^
  File "/home/airflow/.local/lib/python3.12/site-packages/airflow/decorators/base.py", line 266, in execute
    return_value = super().execute(context)
                   ^^^^^^^^^^^^^^^^^^^^^^^^
  File "/home/airflow/.local/lib/python3.12/site-packages/airflow/models/baseoperator.py", line 406, in wrapper
    return func(self, *args, **kwargs)
           ^^^^^^^^^^^^^^^^^^^^^^^^^^^
  File "/home/airflow/.local/lib/python3.12/site-packages/airflow/providers/docker/operators/docker.py", line 495, in execute
    if self.force_pull or not self.cli.images(name=self.image):
                              ^^^^^^^^
  File "/home/airflow/.local/lib/python3.12/site-packages/airflow/providers/docker/operators/docker.py", line 363, in cli
    return self.hook.api_client
           ^^^^^^^^^^^^^^^^^^^^
  File "/usr/local/lib/python3.12/functools.py", line 993, in __get__
    val = self.func(instance)
          ^^^^^^^^^^^^^^^^^^^
  File "/home/airflow/.local/lib/python3.12/site-packages/airflow/providers/docker/hooks/docker.py", line 161, in api_client
    raise AirflowException("Failed to establish connection to any given Docker hosts.")
airflow.exceptions.AirflowException: Failed to establish connection to any given Docker hosts.
[2024-09-18T23:09:47.992+0000] {taskinstance.py:1225} INFO - Marking task as FAILED. dag_id=nba_data_pipeline, task_id=run_data_ingestion, run_id=scheduled__2024-09-17T00:00:00+00:00, execution_date=20240917T000000, start_date=20240918T230947, end_date=20240918T230947
[2024-09-18T23:09:48.005+0000] {taskinstance.py:340} INFO - ::group::Post task execution logs
[2024-09-18T23:09:48.007+0000] {standard_task_runner.py:124} ERROR - Failed to execute job 4 for task run_data_ingestion (Failed to establish connection to any given Docker hosts.; 268)
Traceback (most recent call last):
  File "/home/airflow/.local/lib/python3.12/site-packages/airflow/task/task_runner/standard_task_runner.py", line 117, in _start_by_fork
    ret = args.func(args, dag=self.dag)
          ^^^^^^^^^^^^^^^^^^^^^^^^^^^^^
  File "/home/airflow/.local/lib/python3.12/site-packages/airflow/cli/cli_config.py", line 49, in command
    return func(*args, **kwargs)
           ^^^^^^^^^^^^^^^^^^^^^
  File "/home/airflow/.local/lib/python3.12/site-packages/airflow/utils/cli.py", line 115, in wrapper
    return f(*args, **kwargs)
           ^^^^^^^^^^^^^^^^^^
  File "/home/airflow/.local/lib/python3.12/site-packages/airflow/cli/commands/task_command.py", line 483, in task_run
    task_return_code = _run_task_by_selected_method(args, _dag, ti)
                       ^^^^^^^^^^^^^^^^^^^^^^^^^^^^^^^^^^^^^^^^^^^^
  File "/home/airflow/.local/lib/python3.12/site-packages/airflow/cli/commands/task_command.py", line 256, in _run_task_by_selected_method
    return _run_raw_task(args, ti)
           ^^^^^^^^^^^^^^^^^^^^^^^
  File "/home/airflow/.local/lib/python3.12/site-packages/airflow/cli/commands/task_command.py", line 341, in _run_raw_task
    return ti._run_raw_task(
           ^^^^^^^^^^^^^^^^^
  File "/home/airflow/.local/lib/python3.12/site-packages/airflow/utils/session.py", line 97, in wrapper
    return func(*args, session=session, **kwargs)
           ^^^^^^^^^^^^^^^^^^^^^^^^^^^^^^^^^^^^^^
  File "/home/airflow/.local/lib/python3.12/site-packages/airflow/models/taskinstance.py", line 3004, in _run_raw_task
    return _run_raw_task(
           ^^^^^^^^^^^^^^
  File "/home/airflow/.local/lib/python3.12/site-packages/airflow/models/taskinstance.py", line 273, in _run_raw_task
    TaskInstance._execute_task_with_callbacks(
  File "/home/airflow/.local/lib/python3.12/site-packages/airflow/models/taskinstance.py", line 3158, in _execute_task_with_callbacks
    result = self._execute_task(context, task_orig)
             ^^^^^^^^^^^^^^^^^^^^^^^^^^^^^^^^^^^^^^
  File "/home/airflow/.local/lib/python3.12/site-packages/airflow/models/taskinstance.py", line 3182, in _execute_task
    return _execute_task(self, context, task_orig)
           ^^^^^^^^^^^^^^^^^^^^^^^^^^^^^^^^^^^^^^^
  File "/home/airflow/.local/lib/python3.12/site-packages/airflow/models/taskinstance.py", line 767, in _execute_task
    result = _execute_callable(context=context, **execute_callable_kwargs)
             ^^^^^^^^^^^^^^^^^^^^^^^^^^^^^^^^^^^^^^^^^^^^^^^^^^^^^^^^^^^^^
  File "/home/airflow/.local/lib/python3.12/site-packages/airflow/models/taskinstance.py", line 733, in _execute_callable
    return ExecutionCallableRunner(
           ^^^^^^^^^^^^^^^^^^^^^^^^
  File "/home/airflow/.local/lib/python3.12/site-packages/airflow/utils/operator_helpers.py", line 252, in run
    return self.func(*args, **kwargs)
           ^^^^^^^^^^^^^^^^^^^^^^^^^^
  File "/home/airflow/.local/lib/python3.12/site-packages/airflow/models/baseoperator.py", line 406, in wrapper
    return func(self, *args, **kwargs)
           ^^^^^^^^^^^^^^^^^^^^^^^^^^^
  File "/home/airflow/.local/lib/python3.12/site-packages/airflow/providers/docker/decorators/docker.py", line 199, in execute
    return super().execute(context)
           ^^^^^^^^^^^^^^^^^^^^^^^^
  File "/home/airflow/.local/lib/python3.12/site-packages/airflow/models/baseoperator.py", line 406, in wrapper
    return func(self, *args, **kwargs)
           ^^^^^^^^^^^^^^^^^^^^^^^^^^^
  File "/home/airflow/.local/lib/python3.12/site-packages/airflow/decorators/base.py", line 266, in execute
    return_value = super().execute(context)
                   ^^^^^^^^^^^^^^^^^^^^^^^^
  File "/home/airflow/.local/lib/python3.12/site-packages/airflow/models/baseoperator.py", line 406, in wrapper
    return func(self, *args, **kwargs)
           ^^^^^^^^^^^^^^^^^^^^^^^^^^^
  File "/home/airflow/.local/lib/python3.12/site-packages/airflow/providers/docker/operators/docker.py", line 495, in execute
    if self.force_pull or not self.cli.images(name=self.image):
                              ^^^^^^^^
  File "/home/airflow/.local/lib/python3.12/site-packages/airflow/providers/docker/operators/docker.py", line 363, in cli
    return self.hook.api_client
           ^^^^^^^^^^^^^^^^^^^^
  File "/usr/local/lib/python3.12/functools.py", line 993, in __get__
    val = self.func(instance)
          ^^^^^^^^^^^^^^^^^^^
  File "/home/airflow/.local/lib/python3.12/site-packages/airflow/providers/docker/hooks/docker.py", line 161, in api_client
    raise AirflowException("Failed to establish connection to any given Docker hosts.")
airflow.exceptions.AirflowException: Failed to establish connection to any given Docker hosts.
[2024-09-18T23:09:48.060+0000] {local_task_job_runner.py:266} INFO - Task exited with return code 1
[2024-09-18T23:09:48.086+0000] {taskinstance.py:3900} INFO - 0 downstream tasks scheduled from follow-on schedule check
[2024-09-18T23:09:48.091+0000] {local_task_job_runner.py:245} INFO - ::endgroup::
[2024-09-18T23:23:54.392+0000] {local_task_job_runner.py:123} INFO - ::group::Pre task execution logs
[2024-09-18T23:23:54.412+0000] {taskinstance.py:2612} INFO - Dependencies all met for dep_context=non-requeueable deps ti=<TaskInstance: nba_data_pipeline.run_data_ingestion scheduled__2024-09-17T00:00:00+00:00 [queued]>
[2024-09-18T23:23:54.423+0000] {taskinstance.py:2612} INFO - Dependencies all met for dep_context=requeueable deps ti=<TaskInstance: nba_data_pipeline.run_data_ingestion scheduled__2024-09-17T00:00:00+00:00 [queued]>
[2024-09-18T23:23:54.424+0000] {taskinstance.py:2865} INFO - Starting attempt 2 of 2
[2024-09-18T23:23:54.440+0000] {taskinstance.py:2888} INFO - Executing <Task(_DockerDecoratedOperator): run_data_ingestion> on 2024-09-17 00:00:00+00:00
[2024-09-18T23:23:54.449+0000] {standard_task_runner.py:104} INFO - Running: ['airflow', 'tasks', 'run', 'nba_data_pipeline', 'run_data_ingestion', 'scheduled__2024-09-17T00:00:00+00:00', '--job-id', '4', '--raw', '--subdir', 'DAGS_FOLDER/nba_data_pipeline.py', '--cfg-path', '/tmp/tmp35hvncwm']
[2024-09-18T23:23:54.453+0000] {standard_task_runner.py:105} INFO - Job 4: Subtask run_data_ingestion
[2024-09-18T23:23:54.454+0000] {logging_mixin.py:190} WARNING - /home/airflow/.local/lib/python3.12/site-packages/airflow/task/task_runner/standard_task_runner.py:70 DeprecationWarning: This process (pid=306) is multi-threaded, use of fork() may lead to deadlocks in the child.
[2024-09-18T23:23:54.456+0000] {standard_task_runner.py:72} INFO - Started process 308 to run task
[2024-09-18T23:23:54.512+0000] {task_command.py:467} INFO - Running <TaskInstance: nba_data_pipeline.run_data_ingestion scheduled__2024-09-17T00:00:00+00:00 [running]> on host 880b39d74864
[2024-09-18T23:23:54.602+0000] {taskinstance.py:3131} INFO - Exporting env vars: AIRFLOW_CTX_DAG_OWNER='airflow' AIRFLOW_CTX_DAG_ID='nba_data_pipeline' AIRFLOW_CTX_TASK_ID='run_data_ingestion' AIRFLOW_CTX_EXECUTION_DATE='2024-09-17T00:00:00+00:00' AIRFLOW_CTX_TRY_NUMBER='2' AIRFLOW_CTX_DAG_RUN_ID='scheduled__2024-09-17T00:00:00+00:00'
[2024-09-18T23:23:54.603+0000] {taskinstance.py:731} INFO - ::endgroup::
[2024-09-18T23:23:54.617+0000] {docker.py:157} ERROR - Failed to establish connection to Docker host unix://var/run/docker.sock: Error while fetching server API version: ('Connection aborted.', FileNotFoundError(2, 'No such file or directory'))
[2024-09-18T23:23:54.627+0000] {taskinstance.py:3310} ERROR - Task failed with exception
Traceback (most recent call last):
  File "/home/airflow/.local/lib/python3.12/site-packages/airflow/models/taskinstance.py", line 767, in _execute_task
    result = _execute_callable(context=context, **execute_callable_kwargs)
             ^^^^^^^^^^^^^^^^^^^^^^^^^^^^^^^^^^^^^^^^^^^^^^^^^^^^^^^^^^^^^
  File "/home/airflow/.local/lib/python3.12/site-packages/airflow/models/taskinstance.py", line 733, in _execute_callable
    return ExecutionCallableRunner(
           ^^^^^^^^^^^^^^^^^^^^^^^^
  File "/home/airflow/.local/lib/python3.12/site-packages/airflow/utils/operator_helpers.py", line 252, in run
    return self.func(*args, **kwargs)
           ^^^^^^^^^^^^^^^^^^^^^^^^^^
  File "/home/airflow/.local/lib/python3.12/site-packages/airflow/models/baseoperator.py", line 406, in wrapper
    return func(self, *args, **kwargs)
           ^^^^^^^^^^^^^^^^^^^^^^^^^^^
  File "/home/airflow/.local/lib/python3.12/site-packages/airflow/providers/docker/decorators/docker.py", line 199, in execute
    return super().execute(context)
           ^^^^^^^^^^^^^^^^^^^^^^^^
  File "/home/airflow/.local/lib/python3.12/site-packages/airflow/models/baseoperator.py", line 406, in wrapper
    return func(self, *args, **kwargs)
           ^^^^^^^^^^^^^^^^^^^^^^^^^^^
  File "/home/airflow/.local/lib/python3.12/site-packages/airflow/decorators/base.py", line 266, in execute
    return_value = super().execute(context)
                   ^^^^^^^^^^^^^^^^^^^^^^^^
  File "/home/airflow/.local/lib/python3.12/site-packages/airflow/models/baseoperator.py", line 406, in wrapper
    return func(self, *args, **kwargs)
           ^^^^^^^^^^^^^^^^^^^^^^^^^^^
  File "/home/airflow/.local/lib/python3.12/site-packages/airflow/providers/docker/operators/docker.py", line 495, in execute
    if self.force_pull or not self.cli.images(name=self.image):
                              ^^^^^^^^
  File "/home/airflow/.local/lib/python3.12/site-packages/airflow/providers/docker/operators/docker.py", line 363, in cli
    return self.hook.api_client
           ^^^^^^^^^^^^^^^^^^^^
  File "/usr/local/lib/python3.12/functools.py", line 993, in __get__
    val = self.func(instance)
          ^^^^^^^^^^^^^^^^^^^
  File "/home/airflow/.local/lib/python3.12/site-packages/airflow/providers/docker/hooks/docker.py", line 161, in api_client
    raise AirflowException("Failed to establish connection to any given Docker hosts.")
airflow.exceptions.AirflowException: Failed to establish connection to any given Docker hosts.
[2024-09-18T23:23:54.633+0000] {taskinstance.py:1225} INFO - Marking task as FAILED. dag_id=nba_data_pipeline, task_id=run_data_ingestion, run_id=scheduled__2024-09-17T00:00:00+00:00, execution_date=20240917T000000, start_date=20240918T232354, end_date=20240918T232354
[2024-09-18T23:23:54.644+0000] {taskinstance.py:340} INFO - ::group::Post task execution logs
[2024-09-18T23:23:54.645+0000] {standard_task_runner.py:124} ERROR - Failed to execute job 4 for task run_data_ingestion (Failed to establish connection to any given Docker hosts.; 308)
Traceback (most recent call last):
  File "/home/airflow/.local/lib/python3.12/site-packages/airflow/task/task_runner/standard_task_runner.py", line 117, in _start_by_fork
    ret = args.func(args, dag=self.dag)
          ^^^^^^^^^^^^^^^^^^^^^^^^^^^^^
  File "/home/airflow/.local/lib/python3.12/site-packages/airflow/cli/cli_config.py", line 49, in command
    return func(*args, **kwargs)
           ^^^^^^^^^^^^^^^^^^^^^
  File "/home/airflow/.local/lib/python3.12/site-packages/airflow/utils/cli.py", line 115, in wrapper
    return f(*args, **kwargs)
           ^^^^^^^^^^^^^^^^^^
  File "/home/airflow/.local/lib/python3.12/site-packages/airflow/cli/commands/task_command.py", line 483, in task_run
    task_return_code = _run_task_by_selected_method(args, _dag, ti)
                       ^^^^^^^^^^^^^^^^^^^^^^^^^^^^^^^^^^^^^^^^^^^^
  File "/home/airflow/.local/lib/python3.12/site-packages/airflow/cli/commands/task_command.py", line 256, in _run_task_by_selected_method
    return _run_raw_task(args, ti)
           ^^^^^^^^^^^^^^^^^^^^^^^
  File "/home/airflow/.local/lib/python3.12/site-packages/airflow/cli/commands/task_command.py", line 341, in _run_raw_task
    return ti._run_raw_task(
           ^^^^^^^^^^^^^^^^^
  File "/home/airflow/.local/lib/python3.12/site-packages/airflow/utils/session.py", line 97, in wrapper
    return func(*args, session=session, **kwargs)
           ^^^^^^^^^^^^^^^^^^^^^^^^^^^^^^^^^^^^^^
  File "/home/airflow/.local/lib/python3.12/site-packages/airflow/models/taskinstance.py", line 3004, in _run_raw_task
    return _run_raw_task(
           ^^^^^^^^^^^^^^
  File "/home/airflow/.local/lib/python3.12/site-packages/airflow/models/taskinstance.py", line 273, in _run_raw_task
    TaskInstance._execute_task_with_callbacks(
  File "/home/airflow/.local/lib/python3.12/site-packages/airflow/models/taskinstance.py", line 3158, in _execute_task_with_callbacks
    result = self._execute_task(context, task_orig)
             ^^^^^^^^^^^^^^^^^^^^^^^^^^^^^^^^^^^^^^
  File "/home/airflow/.local/lib/python3.12/site-packages/airflow/models/taskinstance.py", line 3182, in _execute_task
    return _execute_task(self, context, task_orig)
           ^^^^^^^^^^^^^^^^^^^^^^^^^^^^^^^^^^^^^^^
  File "/home/airflow/.local/lib/python3.12/site-packages/airflow/models/taskinstance.py", line 767, in _execute_task
    result = _execute_callable(context=context, **execute_callable_kwargs)
             ^^^^^^^^^^^^^^^^^^^^^^^^^^^^^^^^^^^^^^^^^^^^^^^^^^^^^^^^^^^^^
  File "/home/airflow/.local/lib/python3.12/site-packages/airflow/models/taskinstance.py", line 733, in _execute_callable
    return ExecutionCallableRunner(
           ^^^^^^^^^^^^^^^^^^^^^^^^
  File "/home/airflow/.local/lib/python3.12/site-packages/airflow/utils/operator_helpers.py", line 252, in run
    return self.func(*args, **kwargs)
           ^^^^^^^^^^^^^^^^^^^^^^^^^^
  File "/home/airflow/.local/lib/python3.12/site-packages/airflow/models/baseoperator.py", line 406, in wrapper
    return func(self, *args, **kwargs)
           ^^^^^^^^^^^^^^^^^^^^^^^^^^^
  File "/home/airflow/.local/lib/python3.12/site-packages/airflow/providers/docker/decorators/docker.py", line 199, in execute
    return super().execute(context)
           ^^^^^^^^^^^^^^^^^^^^^^^^
  File "/home/airflow/.local/lib/python3.12/site-packages/airflow/models/baseoperator.py", line 406, in wrapper
    return func(self, *args, **kwargs)
           ^^^^^^^^^^^^^^^^^^^^^^^^^^^
  File "/home/airflow/.local/lib/python3.12/site-packages/airflow/decorators/base.py", line 266, in execute
    return_value = super().execute(context)
                   ^^^^^^^^^^^^^^^^^^^^^^^^
  File "/home/airflow/.local/lib/python3.12/site-packages/airflow/models/baseoperator.py", line 406, in wrapper
    return func(self, *args, **kwargs)
           ^^^^^^^^^^^^^^^^^^^^^^^^^^^
  File "/home/airflow/.local/lib/python3.12/site-packages/airflow/providers/docker/operators/docker.py", line 495, in execute
    if self.force_pull or not self.cli.images(name=self.image):
                              ^^^^^^^^
  File "/home/airflow/.local/lib/python3.12/site-packages/airflow/providers/docker/operators/docker.py", line 363, in cli
    return self.hook.api_client
           ^^^^^^^^^^^^^^^^^^^^
  File "/usr/local/lib/python3.12/functools.py", line 993, in __get__
    val = self.func(instance)
          ^^^^^^^^^^^^^^^^^^^
  File "/home/airflow/.local/lib/python3.12/site-packages/airflow/providers/docker/hooks/docker.py", line 161, in api_client
    raise AirflowException("Failed to establish connection to any given Docker hosts.")
airflow.exceptions.AirflowException: Failed to establish connection to any given Docker hosts.
[2024-09-18T23:23:54.683+0000] {local_task_job_runner.py:266} INFO - Task exited with return code 1
[2024-09-18T23:23:54.710+0000] {taskinstance.py:3900} INFO - 0 downstream tasks scheduled from follow-on schedule check
[2024-09-18T23:23:54.716+0000] {local_task_job_runner.py:245} INFO - ::endgroup::
[2024-09-18T23:46:31.045+0000] {local_task_job_runner.py:123} INFO - ::group::Pre task execution logs
[2024-09-18T23:46:31.065+0000] {taskinstance.py:2612} INFO - Dependencies all met for dep_context=non-requeueable deps ti=<TaskInstance: nba_data_pipeline.run_data_ingestion scheduled__2024-09-17T00:00:00+00:00 [queued]>
[2024-09-18T23:46:31.074+0000] {taskinstance.py:2612} INFO - Dependencies all met for dep_context=requeueable deps ti=<TaskInstance: nba_data_pipeline.run_data_ingestion scheduled__2024-09-17T00:00:00+00:00 [queued]>
[2024-09-18T23:46:31.075+0000] {taskinstance.py:2865} INFO - Starting attempt 2 of 2
[2024-09-18T23:46:31.091+0000] {taskinstance.py:2888} INFO - Executing <Task(DockerOperator): run_data_ingestion> on 2024-09-17 00:00:00+00:00
[2024-09-18T23:46:31.099+0000] {standard_task_runner.py:104} INFO - Running: ['airflow', 'tasks', 'run', 'nba_data_pipeline', 'run_data_ingestion', 'scheduled__2024-09-17T00:00:00+00:00', '--job-id', '4', '--raw', '--subdir', 'DAGS_FOLDER/nba_data_pipeline.py', '--cfg-path', '/tmp/tmpzdigrldo']
[2024-09-18T23:46:31.102+0000] {standard_task_runner.py:105} INFO - Job 4: Subtask run_data_ingestion
[2024-09-18T23:46:31.104+0000] {logging_mixin.py:190} WARNING - /home/airflow/.local/lib/python3.12/site-packages/airflow/task/task_runner/standard_task_runner.py:70 DeprecationWarning: This process (pid=262) is multi-threaded, use of fork() may lead to deadlocks in the child.
[2024-09-18T23:46:31.105+0000] {standard_task_runner.py:72} INFO - Started process 264 to run task
[2024-09-18T23:46:31.154+0000] {task_command.py:467} INFO - Running <TaskInstance: nba_data_pipeline.run_data_ingestion scheduled__2024-09-17T00:00:00+00:00 [running]> on host 05514a690d82
[2024-09-18T23:46:31.267+0000] {taskinstance.py:3131} INFO - Exporting env vars: AIRFLOW_CTX_DAG_OWNER='airflow' AIRFLOW_CTX_DAG_ID='nba_data_pipeline' AIRFLOW_CTX_TASK_ID='run_data_ingestion' AIRFLOW_CTX_EXECUTION_DATE='2024-09-17T00:00:00+00:00' AIRFLOW_CTX_TRY_NUMBER='2' AIRFLOW_CTX_DAG_RUN_ID='scheduled__2024-09-17T00:00:00+00:00'
[2024-09-18T23:46:31.268+0000] {taskinstance.py:731} INFO - ::endgroup::
[2024-09-18T23:46:31.299+0000] {docker.py:367} INFO - Starting docker container from image us-west1-docker.pkg.dev/nba-fantasy-ml/nba-data-pipeline-repo/data-ingestion:latest
[2024-09-18T23:46:31.309+0000] {docker.py:375} WARNING - Using remote engine or docker-in-docker and mounting temporary volume from host is not supported. Falling back to `mount_tmp_dir=False` mode. You can set `mount_tmp_dir` parameter to False to disable mounting and remove the warning
[2024-09-18T23:46:31.545+0000] {docker.py:438} INFO - python: can't open file '/app/data_pipeline_services/data_ingestion/main.py': [Errno 2] No such file or directory
[2024-09-18T23:46:31.689+0000] {taskinstance.py:3310} ERROR - Task failed with exception
Traceback (most recent call last):
  File "/home/airflow/.local/lib/python3.12/site-packages/docker/api/client.py", line 275, in _raise_for_status
    response.raise_for_status()
  File "/home/airflow/.local/lib/python3.12/site-packages/requests/models.py", line 1024, in raise_for_status
    raise HTTPError(http_error_msg, response=self)
requests.exceptions.HTTPError: 400 Client Error: Bad Request for url: http+docker://localhost/v1.47/containers/create

The above exception was the direct cause of the following exception:

Traceback (most recent call last):
  File "/home/airflow/.local/lib/python3.12/site-packages/airflow/providers/docker/operators/docker.py", line 372, in _run_image
    return self._run_image_with_mounts([*self.mounts, tmp_mount], add_tmp_variable=True)
           ^^^^^^^^^^^^^^^^^^^^^^^^^^^^^^^^^^^^^^^^^^^^^^^^^^^^^^^^^^^^^^^^^^^^^^^^^^^^^
  File "/home/airflow/.local/lib/python3.12/site-packages/airflow/providers/docker/operators/docker.py", line 399, in _run_image_with_mounts
    self.container = self.cli.create_container(
                     ^^^^^^^^^^^^^^^^^^^^^^^^^^
  File "/home/airflow/.local/lib/python3.12/site-packages/docker/api/container.py", line 440, in create_container
    return self.create_container_from_config(config, name, platform)
           ^^^^^^^^^^^^^^^^^^^^^^^^^^^^^^^^^^^^^^^^^^^^^^^^^^^^^^^^^
  File "/home/airflow/.local/lib/python3.12/site-packages/docker/api/container.py", line 457, in create_container_from_config
    return self._result(res, True)
           ^^^^^^^^^^^^^^^^^^^^^^^
  File "/home/airflow/.local/lib/python3.12/site-packages/docker/api/client.py", line 281, in _result
    self._raise_for_status(response)
  File "/home/airflow/.local/lib/python3.12/site-packages/docker/api/client.py", line 277, in _raise_for_status
    raise create_api_error_from_http_exception(e) from e
          ^^^^^^^^^^^^^^^^^^^^^^^^^^^^^^^^^^^^^^^
  File "/home/airflow/.local/lib/python3.12/site-packages/docker/errors.py", line 39, in create_api_error_from_http_exception
    raise cls(e, response=response, explanation=explanation) from e
docker.errors.APIError: 400 Client Error for http+docker://localhost/v1.47/containers/create: Bad Request ("invalid mount config for type "bind": bind source path does not exist: /host_mnt/private/tmp/airflowtmp5fcqbbfa")

During handling of the above exception, another exception occurred:

Traceback (most recent call last):
  File "/home/airflow/.local/lib/python3.12/site-packages/airflow/models/taskinstance.py", line 767, in _execute_task
    result = _execute_callable(context=context, **execute_callable_kwargs)
             ^^^^^^^^^^^^^^^^^^^^^^^^^^^^^^^^^^^^^^^^^^^^^^^^^^^^^^^^^^^^^
  File "/home/airflow/.local/lib/python3.12/site-packages/airflow/models/taskinstance.py", line 733, in _execute_callable
    return ExecutionCallableRunner(
           ^^^^^^^^^^^^^^^^^^^^^^^^
  File "/home/airflow/.local/lib/python3.12/site-packages/airflow/utils/operator_helpers.py", line 252, in run
    return self.func(*args, **kwargs)
           ^^^^^^^^^^^^^^^^^^^^^^^^^^
  File "/home/airflow/.local/lib/python3.12/site-packages/airflow/models/baseoperator.py", line 406, in wrapper
    return func(self, *args, **kwargs)
           ^^^^^^^^^^^^^^^^^^^^^^^^^^^
  File "/home/airflow/.local/lib/python3.12/site-packages/airflow/providers/docker/operators/docker.py", line 513, in execute
    return self._run_image()
           ^^^^^^^^^^^^^^^^^
  File "/home/airflow/.local/lib/python3.12/site-packages/airflow/providers/docker/operators/docker.py", line 381, in _run_image
    return self._run_image_with_mounts(self.mounts, add_tmp_variable=False)
           ^^^^^^^^^^^^^^^^^^^^^^^^^^^^^^^^^^^^^^^^^^^^^^^^^^^^^^^^^^^^^^^^
  File "/home/airflow/.local/lib/python3.12/site-packages/airflow/providers/docker/operators/docker.py", line 446, in _run_image_with_mounts
    raise DockerContainerFailedException(f"Docker container failed: {result!r}", logs=log_lines)
airflow.providers.docker.exceptions.DockerContainerFailedException: Docker container failed: {'StatusCode': 2}
[2024-09-18T23:46:31.697+0000] {taskinstance.py:1225} INFO - Marking task as FAILED. dag_id=nba_data_pipeline, task_id=run_data_ingestion, run_id=scheduled__2024-09-17T00:00:00+00:00, execution_date=20240917T000000, start_date=20240918T234631, end_date=20240918T234631
[2024-09-18T23:46:31.711+0000] {taskinstance.py:340} INFO - ::group::Post task execution logs
[2024-09-18T23:46:31.711+0000] {standard_task_runner.py:124} ERROR - Failed to execute job 4 for task run_data_ingestion (Docker container failed: {'StatusCode': 2}; 264)
Traceback (most recent call last):
  File "/home/airflow/.local/lib/python3.12/site-packages/docker/api/client.py", line 275, in _raise_for_status
    response.raise_for_status()
  File "/home/airflow/.local/lib/python3.12/site-packages/requests/models.py", line 1024, in raise_for_status
    raise HTTPError(http_error_msg, response=self)
requests.exceptions.HTTPError: 400 Client Error: Bad Request for url: http+docker://localhost/v1.47/containers/create

The above exception was the direct cause of the following exception:

Traceback (most recent call last):
  File "/home/airflow/.local/lib/python3.12/site-packages/airflow/providers/docker/operators/docker.py", line 372, in _run_image
    return self._run_image_with_mounts([*self.mounts, tmp_mount], add_tmp_variable=True)
           ^^^^^^^^^^^^^^^^^^^^^^^^^^^^^^^^^^^^^^^^^^^^^^^^^^^^^^^^^^^^^^^^^^^^^^^^^^^^^
  File "/home/airflow/.local/lib/python3.12/site-packages/airflow/providers/docker/operators/docker.py", line 399, in _run_image_with_mounts
    self.container = self.cli.create_container(
                     ^^^^^^^^^^^^^^^^^^^^^^^^^^
  File "/home/airflow/.local/lib/python3.12/site-packages/docker/api/container.py", line 440, in create_container
    return self.create_container_from_config(config, name, platform)
           ^^^^^^^^^^^^^^^^^^^^^^^^^^^^^^^^^^^^^^^^^^^^^^^^^^^^^^^^^
  File "/home/airflow/.local/lib/python3.12/site-packages/docker/api/container.py", line 457, in create_container_from_config
    return self._result(res, True)
           ^^^^^^^^^^^^^^^^^^^^^^^
  File "/home/airflow/.local/lib/python3.12/site-packages/docker/api/client.py", line 281, in _result
    self._raise_for_status(response)
  File "/home/airflow/.local/lib/python3.12/site-packages/docker/api/client.py", line 277, in _raise_for_status
    raise create_api_error_from_http_exception(e) from e
          ^^^^^^^^^^^^^^^^^^^^^^^^^^^^^^^^^^^^^^^
  File "/home/airflow/.local/lib/python3.12/site-packages/docker/errors.py", line 39, in create_api_error_from_http_exception
    raise cls(e, response=response, explanation=explanation) from e
docker.errors.APIError: 400 Client Error for http+docker://localhost/v1.47/containers/create: Bad Request ("invalid mount config for type "bind": bind source path does not exist: /host_mnt/private/tmp/airflowtmp5fcqbbfa")

During handling of the above exception, another exception occurred:

Traceback (most recent call last):
  File "/home/airflow/.local/lib/python3.12/site-packages/airflow/task/task_runner/standard_task_runner.py", line 117, in _start_by_fork
    ret = args.func(args, dag=self.dag)
          ^^^^^^^^^^^^^^^^^^^^^^^^^^^^^
  File "/home/airflow/.local/lib/python3.12/site-packages/airflow/cli/cli_config.py", line 49, in command
    return func(*args, **kwargs)
           ^^^^^^^^^^^^^^^^^^^^^
  File "/home/airflow/.local/lib/python3.12/site-packages/airflow/utils/cli.py", line 115, in wrapper
    return f(*args, **kwargs)
           ^^^^^^^^^^^^^^^^^^
  File "/home/airflow/.local/lib/python3.12/site-packages/airflow/cli/commands/task_command.py", line 483, in task_run
    task_return_code = _run_task_by_selected_method(args, _dag, ti)
                       ^^^^^^^^^^^^^^^^^^^^^^^^^^^^^^^^^^^^^^^^^^^^
  File "/home/airflow/.local/lib/python3.12/site-packages/airflow/cli/commands/task_command.py", line 256, in _run_task_by_selected_method
    return _run_raw_task(args, ti)
           ^^^^^^^^^^^^^^^^^^^^^^^
  File "/home/airflow/.local/lib/python3.12/site-packages/airflow/cli/commands/task_command.py", line 341, in _run_raw_task
    return ti._run_raw_task(
           ^^^^^^^^^^^^^^^^^
  File "/home/airflow/.local/lib/python3.12/site-packages/airflow/utils/session.py", line 97, in wrapper
    return func(*args, session=session, **kwargs)
           ^^^^^^^^^^^^^^^^^^^^^^^^^^^^^^^^^^^^^^
  File "/home/airflow/.local/lib/python3.12/site-packages/airflow/models/taskinstance.py", line 3004, in _run_raw_task
    return _run_raw_task(
           ^^^^^^^^^^^^^^
  File "/home/airflow/.local/lib/python3.12/site-packages/airflow/models/taskinstance.py", line 273, in _run_raw_task
    TaskInstance._execute_task_with_callbacks(
  File "/home/airflow/.local/lib/python3.12/site-packages/airflow/models/taskinstance.py", line 3158, in _execute_task_with_callbacks
    result = self._execute_task(context, task_orig)
             ^^^^^^^^^^^^^^^^^^^^^^^^^^^^^^^^^^^^^^
  File "/home/airflow/.local/lib/python3.12/site-packages/airflow/models/taskinstance.py", line 3182, in _execute_task
    return _execute_task(self, context, task_orig)
           ^^^^^^^^^^^^^^^^^^^^^^^^^^^^^^^^^^^^^^^
  File "/home/airflow/.local/lib/python3.12/site-packages/airflow/models/taskinstance.py", line 767, in _execute_task
    result = _execute_callable(context=context, **execute_callable_kwargs)
             ^^^^^^^^^^^^^^^^^^^^^^^^^^^^^^^^^^^^^^^^^^^^^^^^^^^^^^^^^^^^^
  File "/home/airflow/.local/lib/python3.12/site-packages/airflow/models/taskinstance.py", line 733, in _execute_callable
    return ExecutionCallableRunner(
           ^^^^^^^^^^^^^^^^^^^^^^^^
  File "/home/airflow/.local/lib/python3.12/site-packages/airflow/utils/operator_helpers.py", line 252, in run
    return self.func(*args, **kwargs)
           ^^^^^^^^^^^^^^^^^^^^^^^^^^
  File "/home/airflow/.local/lib/python3.12/site-packages/airflow/models/baseoperator.py", line 406, in wrapper
    return func(self, *args, **kwargs)
           ^^^^^^^^^^^^^^^^^^^^^^^^^^^
  File "/home/airflow/.local/lib/python3.12/site-packages/airflow/providers/docker/operators/docker.py", line 513, in execute
    return self._run_image()
           ^^^^^^^^^^^^^^^^^
  File "/home/airflow/.local/lib/python3.12/site-packages/airflow/providers/docker/operators/docker.py", line 381, in _run_image
    return self._run_image_with_mounts(self.mounts, add_tmp_variable=False)
           ^^^^^^^^^^^^^^^^^^^^^^^^^^^^^^^^^^^^^^^^^^^^^^^^^^^^^^^^^^^^^^^^
  File "/home/airflow/.local/lib/python3.12/site-packages/airflow/providers/docker/operators/docker.py", line 446, in _run_image_with_mounts
    raise DockerContainerFailedException(f"Docker container failed: {result!r}", logs=log_lines)
airflow.providers.docker.exceptions.DockerContainerFailedException: Docker container failed: {'StatusCode': 2}
[2024-09-18T23:46:31.740+0000] {local_task_job_runner.py:266} INFO - Task exited with return code 1
[2024-09-18T23:46:31.766+0000] {taskinstance.py:3900} INFO - 0 downstream tasks scheduled from follow-on schedule check
[2024-09-18T23:46:31.770+0000] {local_task_job_runner.py:245} INFO - ::endgroup::
